Workbook

Sheet REKAP PERFORMANCE
A1: ='[1]M268 REKAP'!$C$3 -> 2026 | B1: R
A4: 9 | D4: KREDIVO | J4: Grand Total | L4: HCI | P4: Grand Total | R4: INDODANA | V4: Grand Total | X4: AKULAKU | AB4: Grand Total | AD4: ShopeePay | AF4: Grand Total | AL4: BNPL target 50% to target store | AN4: 0.25 | AU4: 0.15 | AW4: 0.1
D5: =SUBTOTAL(9,D7:D37) -> 0 | E5: =SUBTOTAL(9,E7:E37) -> 0 | F5: =SUBTOTAL(9,F7:F37) -> 292115220 | G5: =SUBTOTAL(9,G7:G37) -> 16 | H5: =SUBTOTAL(9,H7:H37) -> 245211920 | I5: =SUBTOTAL(9,I7:I37) -> 16 | L5: =SUBTOTAL(9,L7:L37) -> 0 | N5: =SUBTOTAL(9,N7:N37) -> 0 | R5: =SUBTOTAL(9,R7:R37) -> 0 | T5: =SUBTOTAL(9,T7:T37) -> 0 | X5: =SUBTOTAL(9,X7:X37) -> 145077000 | Z5: =SUBTOTAL(9,Z7:Z37) -> 0 | AD5: =SUBTOTAL(9,AD7:AD37) -> 90757000 | AH5: =SUBTOTAL(9,AH7:AH37) -> 0 | AI5: =SUBTOTAL(9,AI7:AI37) -> 0 | AJ5: =SUBTOTAL(9,AJ7:AJ37) -> 0 | AL5: ='[1]M268 REKAP'!$D$6 -> 3250000000 | AM5: ='[1]M268 REKAP'!$AE$48 -> 2719799700 | AN5: KREDIVO | AQ5: HCI | AS5: INDODANA | AU5: AKULAKU | AW5: ShopeePay
A6: =DATE(A1,A4,1) -> 46266 | B6: Date | D6: M268 KRE | F6: Debby | H6: Apri | J6: Amount | K6: Qty | P6: Amount | Q6: Qty | V6: Amount | W6: Qty | X6: M268 AKL | AB6: Amount | AC6: Qty | AD6: M268 SPY | AF6: Amount | AG6: Qty | AL6: BNPL | AM6: ='[1]M268 REKAP'!$AD$49 -> BNPL | AN6: =D6 -> M268 KRE | AO6: =F6 -> Debby | AP6: =H6 -> Apri | AQ6: =L6 -> 0 | AR6: =N6 -> 0 | AS6: =R6 -> 0 | AT6: =T6 -> 0 | AU6: =X6 -> M268 AKL | AV6: =Z6 -> 0 | AW6: =AD6 -> M268 SPY
A7: =TEXT(B7,"[$-us]dddd") -> Selasa | B7: =DATE(A1,A4,1) -> 46266 | D7: =SUMIFS('R DATA BNPL'!$G:$G,'R DATA BNPL'!$E:$E,B7,'R DATA BNPL'!$F:$F,'REKAP PERFORMANCE'!$D$6) -> 0 | E7: =SUMIFS('R DATA BNPL'!$H:$H,'R DATA BNPL'!$E:$E,DAILY[[#This Row],[Date]],'R DATA BNPL'!$F:$F,'REKAP PERFORMANCE'!$D$6) -> 0 | F7: =SUMIFS('R DATA BNPL'!$G:$G,'R DATA BNPL'!$E:$E,B7,'R DATA BNPL'!$F:$F,'REKAP PERFORMANCE'!$F$6) -> 0 | G7: =SUMIFS('R DATA BNPL'!$H:$H,'R DATA BNPL'!$E:$E,DAILY[[#This Row],[Date]],'R DATA BNPL'!$F:$F,'REKAP PERFORMANCE'!$F$6) -> 0 | H7: =SUMIFS('R DATA BNPL'!$G:$G,'R DATA BNPL'!$E:$E,B7,'R DATA BNPL'!$F:$F,'REKAP PERFORMANCE'!$H$6) -> 15453000 | I7: =SUMIFS('R DATA BNPL'!$H:$H,'R DATA BNPL'!$E:$E,DAILY[[#This Row],[Date]],'R DATA BNPL'!$F:$F,'REKAP PERFORMANCE'!$H$6) -> 1 | J7: =D7+F7+H7 -> 15453000 | K7: =E7+G7+I7 -> 1 | L7: =SUMIFS('R DATA BNPL'!$G:$G,'R DATA BNPL'!$E:$E,B7,'R DATA BNPL'!$F:$F,'REKAP PERFORMANCE'!$L$6) -> 0 | M7: =SUMIFS('R DATA BNPL'!$H:$H,'R DATA BNPL'!$E:$E,DAILY[[#This Row],[Date]],'R DATA BNPL'!$F:$F,'REKAP PERFORMANCE'!$L$6) -> 0 | N7: =SUMIFS('R DATA BNPL'!$G:$G,'R DATA BNPL'!$E:$E,B7,'R DATA BNPL'!$F:$F,'REKAP PERFORMANCE'!$N$6) -> 0 | O7: =SUMIFS('R DATA BNPL'!$H:$H,'R DATA BNPL'!$E:$E,DAILY[[#This Row],[Date]],'R DATA BNPL'!$F:$F,'REKAP PERFORMANCE'!$N$6) -> 0 | P7: =L7+N7 -> 0 | Q7: =M7+O7 -> 0 | R7: =SUMIFS('R DATA BNPL'!$G:$G,'R DATA BNPL'!$E:$E,B7,'R DATA BNPL'!$F:$F,'REKAP PERFORMANCE'!$R$6) -> 0 | S7: =SUMIFS('R DATA BNPL'!$H:$H,'R DATA BNPL'!$E:$E,DAILY[[#This Row],[Date]],'R DATA BNPL'!$F:$F,'REKAP PERFORMANCE'!$R$6) -> 0 | T7: =SUMIFS('R DATA BNPL'!$G:$G,'R DATA BNPL'!$E:$E,B7,'R DATA BNPL'!$F:$F,'REKAP PERFORMANCE'!$T$6) -> 0 | U7: =SUMIFS('R DATA BNPL'!$H:$H,'R DATA BNPL'!$E:$E,DAILY[[#This Row],[Date]],'R DATA BNPL'!$F:$F,'REKAP PERFORMANCE'!$T$6) -> 0 | V7: =R7+T7 -> 0 | W7: =S7+U7 -> 0 | X7: =SUMIFS('R DATA BNPL'!$G:$G,'R DATA BNPL'!$E:$E,B7,'R DATA BNPL'!$F:$F,'REKAP PERFORMANCE'!$X$6) -> 0 | Y7: =SUMIFS('R DATA BNPL'!$H:$H,'R DATA BNPL'!$E:$E,DAILY[[#This Row],[Date]],'R DATA BNPL'!$F:$F,'REKAP PERFORMANCE'!$X$6) -> 0 | Z7: =SUMIFS('R DATA BNPL'!$G:$G,'R DATA BNPL'!$E:$E,B7,'R DATA BNPL'!$F:$F,'REKAP PERFORMANCE'!$Z$6) -> 0 | AA7: =SUMIFS('R DATA BNPL'!$H:$H,'R DATA BNPL'!$E:$E,DAILY[[#This Row],[Date]],'R DATA BNPL'!$F:$F,'REKAP PERFORMANCE'!$Z$6) -> 0 | AB7: =X7+Z7 -> 0 | AC7: =Y7+AA7 -> 0 | AD7: =SUMIFS('R DATA BNPL'!$G:$G,'R DATA BNPL'!$E:$E,B7,'R DATA BNPL'!$F:$F,'REKAP PERFORMANCE'!$AD$6) -> 0 | AE7: =SUMIFS('R DATA BNPL'!$H:$H,'R DATA BNPL'!$E:$E,DAILY[[#This Row],[Date]],'R DATA BNPL'!$F:$F,'REKAP PERFORMANCE'!$AD$6) -> 0 | AH7: =SUMIFS('R DATA BNPL'!$G:$G,'R DATA BNPL'!$E:$E,B7,'R DATA BNPL'!$F:$F,'REKAP PERFORMANCE'!$AH$6) -> 0 | AI7: =SUMIFS('R DATA BNPL'!$G:$G,'R DATA BNPL'!$E:$E,B7,'R DATA BNPL'!$F:$F,'REKAP PERFORMANCE'!$AI$6) -> 0 | AJ7: =SUMIFS('R DATA BNPL'!$G:$G,'R DATA BNPL'!$E:$E,B7,'R DATA BNPL'!$F:$F,'REKAP PERFORMANCE'!$AJ$6) -> 0 | AM7: Target Dari Store | AN7: =AL5*AN4 -> 812500000 | AQ7: =AL5*AQ4 -> 0 | AS7: =AL5*AS4 -> 0 | AU7: =AL5*AU4 -> 487500000 | AW7: =AL5*AW4 -> 325000000
A8: =TEXT(B8,"[$-us]dddd") -> Rabu | B8: =IF(MONTH(B7+1)=$A$4,B7+1) -> 46267 | D8: =SUMIFS('R DATA BNPL'!$G:$G,'R DATA BNPL'!$E:$E,B8,'R DATA BNPL'!$F:$F,'REKAP PERFORMANCE'!$D$6) -> 0 | E8: =SUMIFS('R DATA BNPL'!$H:$H,'R DATA BNPL'!$E:$E,DAILY[[#This Row],[Date]],'R DATA BNPL'!$F:$F,'REKAP PERFORMANCE'!$D$6) -> 0 | F8: =SUMIFS('R DATA BNPL'!$G:$G,'R DATA BNPL'!$E:$E,B8,'R DATA BNPL'!$F:$F,'REKAP PERFORMANCE'!$F$6) -> 19633309 | G8: =SUMIFS('R DATA BNPL'!$H:$H,'R DATA BNPL'!$E:$E,DAILY[[#This Row],[Date]],'R DATA BNPL'!$F:$F,'REKAP PERFORMANCE'!$F$6) -> 1 | H8: =SUMIFS('R DATA BNPL'!$G:$G,'R DATA BNPL'!$E:$E,B8,'R DATA BNPL'!$F:$F,'REKAP PERFORMANCE'!$H$6) -> 0 | I8: =SUMIFS('R DATA BNPL'!$H:$H,'R DATA BNPL'!$E:$E,DAILY[[#This Row],[Date]],'R DATA BNPL'!$F:$F,'REKAP PERFORMANCE'!$H$6) -> 0 | J8: =D8+F8+H8 -> 19633309 | K8: =E8+G8+I8 -> 1 | L8: =SUMIFS('R DATA BNPL'!$G:$G,'R DATA BNPL'!$E:$E,B8,'R DATA BNPL'!$F:$F,'REKAP PERFORMANCE'!$L$6) -> 0 | M8: =SUMIFS('R DATA BNPL'!$H:$H,'R DATA BNPL'!$E:$E,DAILY[[#This Row],[Date]],'R DATA BNPL'!$F:$F,'REKAP PERFORMANCE'!$L$6) -> 0 | N8: =SUMIFS('R DATA BNPL'!$G:$G,'R DATA BNPL'!$E:$E,B8,'R DATA BNPL'!$F:$F,'REKAP PERFORMANCE'!$N$6) -> 0 | O8: =SUMIFS('R DATA BNPL'!$H:$H,'R DATA BNPL'!$E:$E,DAILY[[#This Row],[Date]],'R DATA BNPL'!$F:$F,'REKAP PERFORMANCE'!$N$6) -> 0 | P8: =L8+N8 -> 0 | Q8: =M8+O8 -> 0 | R8: =SUMIFS('R DATA BNPL'!$G:$G,'R DATA BNPL'!$E:$E,B8,'R DATA BNPL'!$F:$F,'REKAP PERFORMANCE'!$R$6) -> 0 | S8: =SUMIFS('R DATA BNPL'!$H:$H,'R DATA BNPL'!$E:$E,DAILY[[#This Row],[Date]],'R DATA BNPL'!$F:$F,'REKAP PERFORMANCE'!$R$6) -> 0 | T8: =SUMIFS('R DATA BNPL'!$G:$G,'R DATA BNPL'!$E:$E,B8,'R DATA BNPL'!$F:$F,'REKAP PERFORMANCE'!$T$6) -> 0 | U8: =SUMIFS('R DATA BNPL'!$H:$H,'R DATA BNPL'!$E:$E,DAILY[[#This Row],[Date]],'R DATA BNPL'!$F:$F,'REKAP PERFORMANCE'!$T$6) -> 0 | V8: =R8+T8 -> 0 | W8: =S8+U8 -> 0 | X8: =SUMIFS('R DATA BNPL'!$G:$G,'R DATA BNPL'!$E:$E,B8,'R DATA BNPL'!$F:$F,'REKAP PERFORMANCE'!$X$6) -> 0 | Y8: =SUMIFS('R DATA BNPL'!$H:$H,'R DATA BNPL'!$E:$E,DAILY[[#This Row],[Date]],'R DATA BNPL'!$F:$F,'REKAP PERFORMANCE'!$X$6) -> 0 | Z8: =SUMIFS('R DATA BNPL'!$G:$G,'R DATA BNPL'!$E:$E,B8,'R DATA BNPL'!$F:$F,'REKAP PERFORMANCE'!$Z$6) -> 0 | AA8: =SUMIFS('R DATA BNPL'!$H:$H,'R DATA BNPL'!$E:$E,DAILY[[#This Row],[Date]],'R DATA BNPL'!$F:$F,'REKAP PERFORMANCE'!$Z$6) -> 0 | AB8: =X8+Z8 -> 0 | AC8: =Y8+AA8 -> 0 | AD8: =SUMIFS('R DATA BNPL'!$G:$G,'R DATA BNPL'!$E:$E,B8,'R DATA BNPL'!$F:$F,'REKAP PERFORMANCE'!$AD$6) -> 0 | AE8: =SUMIFS('R DATA BNPL'!$H:$H,'R DATA BNPL'!$E:$E,DAILY[[#This Row],[Date]],'R DATA BNPL'!$F:$F,'REKAP PERFORMANCE'!$AD$6) -> 0 | AH8: =SUMIFS('R DATA BNPL'!$G:$G,'R DATA BNPL'!$E:$E,B8,'R DATA BNPL'!$F:$F,'REKAP PERFORMANCE'!$AH$6) -> 0 | AI8: =SUMIFS('R DATA BNPL'!$G:$G,'R DATA BNPL'!$E:$E,B8,'R DATA BNPL'!$F:$F,'REKAP PERFORMANCE'!$AI$6) -> 0 | AJ8: =SUMIFS('R DATA BNPL'!$G:$G,'R DATA BNPL'!$E:$E,B8,'R DATA BNPL'!$F:$F,'REKAP PERFORMANCE'!$AJ$6) -> 0 | AM8: Target BNPL | AN8: =$AN$7*AN14 -> 0 | AO8: =$AN$7*AO14 -> 406250000 | AP8: =$AN$7*AP14 -> 406250000 | AQ8: =AQ7/2 -> 0 | AR8: =AQ7/2 -> 0 | AS8: =AS7/2 -> 0 | AT8: =AS7/2 -> 0 | AU8: =$AU$7*AU14 -> 487500000 | AV8: =$AU$7*AV14 -> 0 | AW8: =AW7*AW14 -> 325000000
A9: =TEXT(B9,"[$-us]dddd") -> Kamis | B9: =IF(MONTH(B8+1)=$A$4,B8+1) -> 46268 | D9: =SUMIFS('R DATA BNPL'!$G:$G,'R DATA BNPL'!$E:$E,B9,'R DATA BNPL'!$F:$F,'REKAP PERFORMANCE'!$D$6) -> 0 | E9: =SUMIFS('R DATA BNPL'!$H:$H,'R DATA BNPL'!$E:$E,DAILY[[#This Row],[Date]],'R DATA BNPL'!$F:$F,'REKAP PERFORMANCE'!$D$6) -> 0 | F9: =SUMIFS('R DATA BNPL'!$G:$G,'R DATA BNPL'!$E:$E,B9,'R DATA BNPL'!$F:$F,'REKAP PERFORMANCE'!$F$6) -> 17827381 | G9: =SUMIFS('R DATA BNPL'!$H:$H,'R DATA BNPL'!$E:$E,DAILY[[#This Row],[Date]],'R DATA BNPL'!$F:$F,'REKAP PERFORMANCE'!$F$6) -> 1 | H9: =SUMIFS('R DATA BNPL'!$G:$G,'R DATA BNPL'!$E:$E,B9,'R DATA BNPL'!$F:$F,'REKAP PERFORMANCE'!$H$6) -> 0 | I9: =SUMIFS('R DATA BNPL'!$H:$H,'R DATA BNPL'!$E:$E,DAILY[[#This Row],[Date]],'R DATA BNPL'!$F:$F,'REKAP PERFORMANCE'!$H$6) -> 0 | J9: =D9+F9+H9 -> 17827381 | K9: =E9+G9+I9 -> 1 | L9: =SUMIFS('R DATA BNPL'!$G:$G,'R DATA BNPL'!$E:$E,B9,'R DATA BNPL'!$F:$F,'REKAP PERFORMANCE'!$L$6) -> 0 | M9: =SUMIFS('R DATA BNPL'!$H:$H,'R DATA BNPL'!$E:$E,DAILY[[#This Row],[Date]],'R DATA BNPL'!$F:$F,'REKAP PERFORMANCE'!$L$6) -> 0 | N9: =SUMIFS('R DATA BNPL'!$G:$G,'R DATA BNPL'!$E:$E,B9,'R DATA BNPL'!$F:$F,'REKAP PERFORMANCE'!$N$6) -> 0 | O9: =SUMIFS('R DATA BNPL'!$H:$H,'R DATA BNPL'!$E:$E,DAILY[[#This Row],[Date]],'R DATA BNPL'!$F:$F,'REKAP PERFORMANCE'!$N$6) -> 0 | P9: =L9+N9 -> 0 | Q9: =M9+O9 -> 0 | R9: =SUMIFS('R DATA BNPL'!$G:$G,'R DATA BNPL'!$E:$E,B9,'R DATA BNPL'!$F:$F,'REKAP PERFORMANCE'!$R$6) -> 0 | S9: =SUMIFS('R DATA BNPL'!$H:$H,'R DATA BNPL'!$E:$E,DAILY[[#This Row],[Date]],'R DATA BNPL'!$F:$F,'REKAP PERFORMANCE'!$R$6) -> 0 | T9: =SUMIFS('R DATA BNPL'!$G:$G,'R DATA BNPL'!$E:$E,B9,'R DATA BNPL'!$F:$F,'REKAP PERFORMANCE'!$T$6) -> 0 | U9: =SUMIFS('R DATA BNPL'!$H:$H,'R DATA BNPL'!$E:$E,DAILY[[#This Row],[Date]],'R DATA BNPL'!$F:$F,'REKAP PERFORMANCE'!$T$6) -> 0 | V9: =R9+T9 -> 0 | W9: =S9+U9 -> 0 | X9: =SUMIFS('R DATA BNPL'!$G:$G,'R DATA BNPL'!$E:$E,B9,'R DATA BNPL'!$F:$F,'REKAP PERFORMANCE'!$X$6) -> 0 | Y9: =SUMIFS('R DATA BNPL'!$H:$H,'R DATA BNPL'!$E:$E,DAILY[[#This Row],[Date]],'R DATA BNPL'!$F:$F,'REKAP PERFORMANCE'!$X$6) -> 0 | Z9: =SUMIFS('R DATA BNPL'!$G:$G,'R DATA BNPL'!$E:$E,B9,'R DATA BNPL'!$F:$F,'REKAP PERFORMANCE'!$Z$6) -> 0 | AA9: =SUMIFS('R DATA BNPL'!$H:$H,'R DATA BNPL'!$E:$E,DAILY[[#This Row],[Date]],'R DATA BNPL'!$F:$F,'REKAP PERFORMANCE'!$Z$6) -> 0 | AB9: =X9+Z9 -> 0 | AC9: =Y9+AA9 -> 0 | AD9: =SUMIFS('R DATA BNPL'!$G:$G,'R DATA BNPL'!$E:$E,B9,'R DATA BNPL'!$F:$F,'REKAP PERFORMANCE'!$AD$6) -> 0 | AE9: =SUMIFS('R DATA BNPL'!$H:$H,'R DATA BNPL'!$E:$E,DAILY[[#This Row],[Date]],'R DATA BNPL'!$F:$F,'REKAP PERFORMANCE'!$AD$6) -> 0 | AH9: =SUMIFS('R DATA BNPL'!$G:$G,'R DATA BNPL'!$E:$E,B9,'R DATA BNPL'!$F:$F,'REKAP PERFORMANCE'!$AH$6) -> 0 | AI9: =SUMIFS('R DATA BNPL'!$G:$G,'R DATA BNPL'!$E:$E,B9,'R DATA BNPL'!$F:$F,'REKAP PERFORMANCE'!$AI$6) -> 0 | AJ9: =SUMIFS('R DATA BNPL'!$G:$G,'R DATA BNPL'!$E:$E,B9,'R DATA BNPL'!$F:$F,'REKAP PERFORMANCE'!$AJ$6) -> 0 | AM9: Achievement BNPL | AN9: =D5 -> 0 | AO9: =F5 -> 292115220 | AP9: =H5 -> 245211920 | AQ9: =L5 -> 0 | AR9: =N5 -> 0 | AS9: =R5 -> 0 | AT9: =T5 -> 0 | AU9: =X5 -> 145077000 | AV9: =Z5 -> 0 | AW9: =AD5 -> 90757000
A10: =TEXT(B10,"[$-us]dddd") -> Jumat | B10: =IF(MONTH(B9+1)=$A$4,B9+1) -> 46269 | D10: =SUMIFS('R DATA BNPL'!$G:$G,'R DATA BNPL'!$E:$E,B10,'R DATA BNPL'!$F:$F,'REKAP PERFORMANCE'!$D$6) -> 0 | E10: =SUMIFS('R DATA BNPL'!$H:$H,'R DATA BNPL'!$E:$E,DAILY[[#This Row],[Date]],'R DATA BNPL'!$F:$F,'REKAP PERFORMANCE'!$D$6) -> 0 | F10: =SUMIFS('R DATA BNPL'!$G:$G,'R DATA BNPL'!$E:$E,B10,'R DATA BNPL'!$F:$F,'REKAP PERFORMANCE'!$F$6) -> 0 | G10: =SUMIFS('R DATA BNPL'!$H:$H,'R DATA BNPL'!$E:$E,DAILY[[#This Row],[Date]],'R DATA BNPL'!$F:$F,'REKAP PERFORMANCE'!$F$6) -> 0 | H10: =SUMIFS('R DATA BNPL'!$G:$G,'R DATA BNPL'!$E:$E,B10,'R DATA BNPL'!$F:$F,'REKAP PERFORMANCE'!$H$6) -> 26544200 | I10: =SUMIFS('R DATA BNPL'!$H:$H,'R DATA BNPL'!$E:$E,DAILY[[#This Row],[Date]],'R DATA BNPL'!$F:$F,'REKAP PERFORMANCE'!$H$6) -> 2 | J10: =D10+F10+H10 -> 26544200 | K10: =E10+G10+I10 -> 2 | L10: =SUMIFS('R DATA BNPL'!$G:$G,'R DATA BNPL'!$E:$E,B10,'R DATA BNPL'!$F:$F,'REKAP PERFORMANCE'!$L$6) -> 0 | M10: =SUMIFS('R DATA BNPL'!$H:$H,'R DATA BNPL'!$E:$E,DAILY[[#This Row],[Date]],'R DATA BNPL'!$F:$F,'REKAP PERFORMANCE'!$L$6) -> 0 | N10: =SUMIFS('R DATA BNPL'!$G:$G,'R DATA BNPL'!$E:$E,B10,'R DATA BNPL'!$F:$F,'REKAP PERFORMANCE'!$N$6) -> 0 | O10: =SUMIFS('R DATA BNPL'!$H:$H,'R DATA BNPL'!$E:$E,DAILY[[#This Row],[Date]],'R DATA BNPL'!$F:$F,'REKAP PERFORMANCE'!$N$6) -> 0 | P10: =L10+N10 -> 0 | Q10: =M10+O10 -> 0 | R10: =SUMIFS('R DATA BNPL'!$G:$G,'R DATA BNPL'!$E:$E,B10,'R DATA BNPL'!$F:$F,'REKAP PERFORMANCE'!$R$6) -> 0 | S10: =SUMIFS('R DATA BNPL'!$H:$H,'R DATA BNPL'!$E:$E,DAILY[[#This Row],[Date]],'R DATA BNPL'!$F:$F,'REKAP PERFORMANCE'!$R$6) -> 0 | T10: =SUMIFS('R DATA BNPL'!$G:$G,'R DATA BNPL'!$E:$E,B10,'R DATA BNPL'!$F:$F,'REKAP PERFORMANCE'!$T$6) -> 0 | U10: =SUMIFS('R DATA BNPL'!$H:$H,'R DATA BNPL'!$E:$E,DAILY[[#This Row],[Date]],'R DATA BNPL'!$F:$F,'REKAP PERFORMANCE'!$T$6) -> 0 | V10: =R10+T10 -> 0 | W10: =S10+U10 -> 0 | X10: =SUMIFS('R DATA BNPL'!$G:$G,'R DATA BNPL'!$E:$E,B10,'R DATA BNPL'!$F:$F,'REKAP PERFORMANCE'!$X$6) -> 0 | Y10: =SUMIFS('R DATA BNPL'!$H:$H,'R DATA BNPL'!$E:$E,DAILY[[#This Row],[Date]],'R DATA BNPL'!$F:$F,'REKAP PERFORMANCE'!$X$6) -> 0 | Z10: =SUMIFS('R DATA BNPL'!$G:$G,'R DATA BNPL'!$E:$E,B10,'R DATA BNPL'!$F:$F,'REKAP PERFORMANCE'!$Z$6) -> 0 | AA10: =SUMIFS('R DATA BNPL'!$H:$H,'R DATA BNPL'!$E:$E,DAILY[[#This Row],[Date]],'R DATA BNPL'!$F:$F,'REKAP PERFORMANCE'!$Z$6) -> 0 | AB10: =X10+Z10 -> 0 | AC10: =Y10+AA10 -> 0 | AD10: =SUMIFS('R DATA BNPL'!$G:$G,'R DATA BNPL'!$E:$E,B10,'R DATA BNPL'!$F:$F,'REKAP PERFORMANCE'!$AD$6) -> 17999000 | AE10: =SUMIFS('R DATA BNPL'!$H:$H,'R DATA BNPL'!$E:$E,DAILY[[#This Row],[Date]],'R DATA BNPL'!$F:$F,'REKAP PERFORMANCE'!$AD$6) -> 1 | AH10: =SUMIFS('R DATA BNPL'!$G:$G,'R DATA BNPL'!$E:$E,B10,'R DATA BNPL'!$F:$F,'REKAP PERFORMANCE'!$AH$6) -> 0 | AI10: =SUMIFS('R DATA BNPL'!$G:$G,'R DATA BNPL'!$E:$E,B10,'R DATA BNPL'!$F:$F,'REKAP PERFORMANCE'!$AI$6) -> 0 | AJ10: =SUMIFS('R DATA BNPL'!$G:$G,'R DATA BNPL'!$E:$E,B10,'R DATA BNPL'!$F:$F,'REKAP PERFORMANCE'!$AJ$6) -> 0 | AM10: Selisih | AN10: =AN9-AN8 -> 0 | AO10: =AO9-AO8 -> -114134780 | AP10: =AP9-AP8 -> -161038080 | AQ10: =AQ9-AQ8 -> 0 | AR10: =AR9-AR8 -> 0 | AS10: =AS9-AS8 -> 0 | AT10: =AT9-AT8 -> 0 | AU10: =AU9-AU8 -> -342423000 | ... AW10: =AW9-AW8 -> -234243000
A11: =TEXT(B11,"[$-us]dddd") -> Sabtu | B11: =IF(MONTH(B10+1)=$A$4,B10+1) -> 46270 | D11: =SUMIFS('R DATA BNPL'!$G:$G,'R DATA BNPL'!$E:$E,B11,'R DATA BNPL'!$F:$F,'REKAP PERFORMANCE'!$D$6) -> 0 | E11: =SUMIFS('R DATA BNPL'!$H:$H,'R DATA BNPL'!$E:$E,DAILY[[#This Row],[Date]],'R DATA BNPL'!$F:$F,'REKAP PERFORMANCE'!$D$6) -> 0 | F11: =SUMIFS('R DATA BNPL'!$G:$G,'R DATA BNPL'!$E:$E,B11,'R DATA BNPL'!$F:$F,'REKAP PERFORMANCE'!$F$6) -> 36812480 | G11: =SUMIFS('R DATA BNPL'!$H:$H,'R DATA BNPL'!$E:$E,DAILY[[#This Row],[Date]],'R DATA BNPL'!$F:$F,'REKAP PERFORMANCE'!$F$6) -> 1 | H11: =SUMIFS('R DATA BNPL'!$G:$G,'R DATA BNPL'!$E:$E,B11,'R DATA BNPL'!$F:$F,'REKAP PERFORMANCE'!$H$6) -> 43860260 | I11: =SUMIFS('R DATA BNPL'!$H:$H,'R DATA BNPL'!$E:$E,DAILY[[#This Row],[Date]],'R DATA BNPL'!$F:$F,'REKAP PERFORMANCE'!$H$6) -> 2 | J11: =D11+F11+H11 -> 80672740 | K11: =E11+G11+I11 -> 3 | L11: =SUMIFS('R DATA BNPL'!$G:$G,'R DATA BNPL'!$E:$E,B11,'R DATA BNPL'!$F:$F,'REKAP PERFORMANCE'!$L$6) -> 0 | M11: =SUMIFS('R DATA BNPL'!$H:$H,'R DATA BNPL'!$E:$E,DAILY[[#This Row],[Date]],'R DATA BNPL'!$F:$F,'REKAP PERFORMANCE'!$L$6) -> 0 | N11: =SUMIFS('R DATA BNPL'!$G:$G,'R DATA BNPL'!$E:$E,B11,'R DATA BNPL'!$F:$F,'REKAP PERFORMANCE'!$N$6) -> 0 | O11: =SUMIFS('R DATA BNPL'!$H:$H,'R DATA BNPL'!$E:$E,DAILY[[#This Row],[Date]],'R DATA BNPL'!$F:$F,'REKAP PERFORMANCE'!$N$6) -> 0 | P11: =L11+N11 -> 0 | Q11: =M11+O11 -> 0 | R11: =SUMIFS('R DATA BNPL'!$G:$G,'R DATA BNPL'!$E:$E,B11,'R DATA BNPL'!$F:$F,'REKAP PERFORMANCE'!$R$6) -> 0 | S11: =SUMIFS('R DATA BNPL'!$H:$H,'R DATA BNPL'!$E:$E,DAILY[[#This Row],[Date]],'R DATA BNPL'!$F:$F,'REKAP PERFORMANCE'!$R$6) -> 0 | T11: =SUMIFS('R DATA BNPL'!$G:$G,'R DATA BNPL'!$E:$E,B11,'R DATA BNPL'!$F:$F,'REKAP PERFORMANCE'!$T$6) -> 0 | U11: =SUMIFS('R DATA BNPL'!$H:$H,'R DATA BNPL'!$E:$E,DAILY[[#This Row],[Date]],'R DATA BNPL'!$F:$F,'REKAP PERFORMANCE'!$T$6) -> 0 | V11: =R11+T11 -> 0 | W11: =S11+U11 -> 0 | X11: =SUMIFS('R DATA BNPL'!$G:$G,'R DATA BNPL'!$E:$E,B11,'R DATA BNPL'!$F:$F,'REKAP PERFORMANCE'!$X$6) -> 17208000 | Y11: =SUMIFS('R DATA BNPL'!$H:$H,'R DATA BNPL'!$E:$E,DAILY[[#This Row],[Date]],'R DATA BNPL'!$F:$F,'REKAP PERFORMANCE'!$X$6) -> 1 | Z11: =SUMIFS('R DATA BNPL'!$G:$G,'R DATA BNPL'!$E:$E,B11,'R DATA BNPL'!$F:$F,'REKAP PERFORMANCE'!$Z$6) -> 0 | AA11: =SUMIFS('R DATA BNPL'!$H:$H,'R DATA BNPL'!$E:$E,DAILY[[#This Row],[Date]],'R DATA BNPL'!$F:$F,'REKAP PERFORMANCE'!$Z$6) -> 0 | AB11: =X11+Z11 -> 17208000 | AC11: =Y11+AA11 -> 1 | AD11: =SUMIFS('R DATA BNPL'!$G:$G,'R DATA BNPL'!$E:$E,B11,'R DATA BNPL'!$F:$F,'REKAP PERFORMANCE'!$AD$6) -> 16749000 | AE11: =SUMIFS('R DATA BNPL'!$H:$H,'R DATA BNPL'!$E:$E,DAILY[[#This Row],[Date]],'R DATA BNPL'!$F:$F,'REKAP PERFORMANCE'!$AD$6) -> 1 | AH11: =SUMIFS('R DATA BNPL'!$G:$G,'R DATA BNPL'!$E:$E,B11,'R DATA BNPL'!$F:$F,'REKAP PERFORMANCE'!$AH$6) -> 0 | AI11: =SUMIFS('R DATA BNPL'!$G:$G,'R DATA BNPL'!$E:$E,B11,'R DATA BNPL'!$F:$F,'REKAP PERFORMANCE'!$AI$6) -> 0 | AJ11: =SUMIFS('R DATA BNPL'!$G:$G,'R DATA BNPL'!$E:$E,B11,'R DATA BNPL'!$F:$F,'REKAP PERFORMANCE'!$AJ$6) -> 0 | AM11: Hit% | AN11: =IFERROR(AN9/AN8,0) -> 0 | AO11: =IFERROR(AO9/AO8,0) -> 0.71905285 | AP11: =IFERROR(AP9/AP8,0) -> 0.60359857 | AQ11: =IFERROR(AQ9/AQ8,0) -> 0 | AR11: =IFERROR(AR9/AR8,0) -> 0 | AS11: =IFERROR(AS9/AS8,0) -> 0 | AT11: =IFERROR(AT9/AT8,0) -> 0 | AU11: =IFERROR(AU9/AU8,0) -> 0.29759385 | ... AW11: =IFERROR(AW9/AW8,0) -> 0.27925231
A12: =TEXT(B12,"[$-us]dddd") -> Minggu | B12: =IF(MONTH(B11+1)=$A$4,B11+1) -> 46271 | D12: =SUMIFS('R DATA BNPL'!$G:$G,'R DATA BNPL'!$E:$E,B12,'R DATA BNPL'!$F:$F,'REKAP PERFORMANCE'!$D$6) -> 0 | E12: =SUMIFS('R DATA BNPL'!$H:$H,'R DATA BNPL'!$E:$E,DAILY[[#This Row],[Date]],'R DATA BNPL'!$F:$F,'REKAP PERFORMANCE'!$D$6) -> 0 | F12: =SUMIFS('R DATA BNPL'!$G:$G,'R DATA BNPL'!$E:$E,B12,'R DATA BNPL'!$F:$F,'REKAP PERFORMANCE'!$F$6) -> 47851980 | G12: =SUMIFS('R DATA BNPL'!$H:$H,'R DATA BNPL'!$E:$E,DAILY[[#This Row],[Date]],'R DATA BNPL'!$F:$F,'REKAP PERFORMANCE'!$F$6) -> 3 | H12: =SUMIFS('R DATA BNPL'!$G:$G,'R DATA BNPL'!$E:$E,B12,'R DATA BNPL'!$F:$F,'REKAP PERFORMANCE'!$H$6) -> 0 | I12: =SUMIFS('R DATA BNPL'!$H:$H,'R DATA BNPL'!$E:$E,DAILY[[#This Row],[Date]],'R DATA BNPL'!$F:$F,'REKAP PERFORMANCE'!$H$6) -> 0 | J12: =D12+F12+H12 -> 47851980 | K12: =E12+G12+I12 -> 3 | L12: =SUMIFS('R DATA BNPL'!$G:$G,'R DATA BNPL'!$E:$E,B12,'R DATA BNPL'!$F:$F,'REKAP PERFORMANCE'!$L$6) -> 0 | M12: =SUMIFS('R DATA BNPL'!$H:$H,'R DATA BNPL'!$E:$E,DAILY[[#This Row],[Date]],'R DATA BNPL'!$F:$F,'REKAP PERFORMANCE'!$L$6) -> 0 | N12: =SUMIFS('R DATA BNPL'!$G:$G,'R DATA BNPL'!$E:$E,B12,'R DATA BNPL'!$F:$F,'REKAP PERFORMANCE'!$N$6) -> 0 | O12: =SUMIFS('R DATA BNPL'!$H:$H,'R DATA BNPL'!$E:$E,DAILY[[#This Row],[Date]],'R DATA BNPL'!$F:$F,'REKAP PERFORMANCE'!$N$6) -> 0 | P12: =L12+N12 -> 0 | Q12: =M12+O12 -> 0 | R12: =SUMIFS('R DATA BNPL'!$G:$G,'R DATA BNPL'!$E:$E,B12,'R DATA BNPL'!$F:$F,'REKAP PERFORMANCE'!$R$6) -> 0 | S12: =SUMIFS('R DATA BNPL'!$H:$H,'R DATA BNPL'!$E:$E,DAILY[[#This Row],[Date]],'R DATA BNPL'!$F:$F,'REKAP PERFORMANCE'!$R$6) -> 0 | T12: =SUMIFS('R DATA BNPL'!$G:$G,'R DATA BNPL'!$E:$E,B12,'R DATA BNPL'!$F:$F,'REKAP PERFORMANCE'!$T$6) -> 0 | U12: =SUMIFS('R DATA BNPL'!$H:$H,'R DATA BNPL'!$E:$E,DAILY[[#This Row],[Date]],'R DATA BNPL'!$F:$F,'REKAP PERFORMANCE'!$T$6) -> 0 | V12: =R12+T12 -> 0 | W12: =S12+U12 -> 0 | X12: =SUMIFS('R DATA BNPL'!$G:$G,'R DATA BNPL'!$E:$E,B12,'R DATA BNPL'!$F:$F,'REKAP PERFORMANCE'!$X$6) -> 13909000 | Y12: =SUMIFS('R DATA BNPL'!$H:$H,'R DATA BNPL'!$E:$E,DAILY[[#This Row],[Date]],'R DATA BNPL'!$F:$F,'REKAP PERFORMANCE'!$X$6) -> 1 | Z12: =SUMIFS('R DATA BNPL'!$G:$G,'R DATA BNPL'!$E:$E,B12,'R DATA BNPL'!$F:$F,'REKAP PERFORMANCE'!$Z$6) -> 0 | AA12: =SUMIFS('R DATA BNPL'!$H:$H,'R DATA BNPL'!$E:$E,DAILY[[#This Row],[Date]],'R DATA BNPL'!$F:$F,'REKAP PERFORMANCE'!$Z$6) -> 0 | AB12: =X12+Z12 -> 13909000 | AC12: =Y12+AA12 -> 1 | AD12: =SUMIFS('R DATA BNPL'!$G:$G,'R DATA BNPL'!$E:$E,B12,'R DATA BNPL'!$F:$F,'REKAP PERFORMANCE'!$AD$6) -> 0 | AE12: =SUMIFS('R DATA BNPL'!$H:$H,'R DATA BNPL'!$E:$E,DAILY[[#This Row],[Date]],'R DATA BNPL'!$F:$F,'REKAP PERFORMANCE'!$AD$6) -> 0 | AH12: =SUMIFS('R DATA BNPL'!$G:$G,'R DATA BNPL'!$E:$E,B12,'R DATA BNPL'!$F:$F,'REKAP PERFORMANCE'!$AH$6) -> 0 | AI12: =SUMIFS('R DATA BNPL'!$G:$G,'R DATA BNPL'!$E:$E,B12,'R DATA BNPL'!$F:$F,'REKAP PERFORMANCE'!$AI$6) -> 0 | AJ12: =SUMIFS('R DATA BNPL'!$G:$G,'R DATA BNPL'!$E:$E,B12,'R DATA BNPL'!$F:$F,'REKAP PERFORMANCE'!$AJ$6) -> 0 | AM12: Contribution To Store % | AN12: =IFERROR(AN13/AM5,0) -> 0.19756129 | AU12: =IFERROR(AU13/AM5,0) -> 0.05334106 | AW12: =IFERROR(AW13/AM5,0) -> 0.033369001
A13: =TEXT(B13,"[$-us]dddd") -> Senin | B13: =IF(MONTH(B12+1)=$A$4,B12+1) -> 46272 | D13: =SUMIFS('R DATA BNPL'!$G:$G,'R DATA BNPL'!$E:$E,B13,'R DATA BNPL'!$F:$F,'REKAP PERFORMANCE'!$D$6) -> 0 | E13: =SUMIFS('R DATA BNPL'!$H:$H,'R DATA BNPL'!$E:$E,DAILY[[#This Row],[Date]],'R DATA BNPL'!$F:$F,'REKAP PERFORMANCE'!$D$6) -> 0 | F13: =SUMIFS('R DATA BNPL'!$G:$G,'R DATA BNPL'!$E:$E,B13,'R DATA BNPL'!$F:$F,'REKAP PERFORMANCE'!$F$6) -> 11019100 | G13: =SUMIFS('R DATA BNPL'!$H:$H,'R DATA BNPL'!$E:$E,DAILY[[#This Row],[Date]],'R DATA BNPL'!$F:$F,'REKAP PERFORMANCE'!$F$6) -> 2 | H13: =SUMIFS('R DATA BNPL'!$G:$G,'R DATA BNPL'!$E:$E,B13,'R DATA BNPL'!$F:$F,'REKAP PERFORMANCE'!$H$6) -> 0 | I13: =SUMIFS('R DATA BNPL'!$H:$H,'R DATA BNPL'!$E:$E,DAILY[[#This Row],[Date]],'R DATA BNPL'!$F:$F,'REKAP PERFORMANCE'!$H$6) -> 0 | J13: =D13+F13+H13 -> 11019100 | K13: =E13+G13+I13 -> 2 | L13: =SUMIFS('R DATA BNPL'!$G:$G,'R DATA BNPL'!$E:$E,B13,'R DATA BNPL'!$F:$F,'REKAP PERFORMANCE'!$L$6) -> 0 | M13: =SUMIFS('R DATA BNPL'!$H:$H,'R DATA BNPL'!$E:$E,DAILY[[#This Row],[Date]],'R DATA BNPL'!$F:$F,'REKAP PERFORMANCE'!$L$6) -> 0 | N13: =SUMIFS('R DATA BNPL'!$G:$G,'R DATA BNPL'!$E:$E,B13,'R DATA BNPL'!$F:$F,'REKAP PERFORMANCE'!$N$6) -> 0 | O13: =SUMIFS('R DATA BNPL'!$H:$H,'R DATA BNPL'!$E:$E,DAILY[[#This Row],[Date]],'R DATA BNPL'!$F:$F,'REKAP PERFORMANCE'!$N$6) -> 0 | P13: =L13+N13 -> 0 | Q13: =M13+O13 -> 0 | R13: =SUMIFS('R DATA BNPL'!$G:$G,'R DATA BNPL'!$E:$E,B13,'R DATA BNPL'!$F:$F,'REKAP PERFORMANCE'!$R$6) -> 0 | S13: =SUMIFS('R DATA BNPL'!$H:$H,'R DATA BNPL'!$E:$E,DAILY[[#This Row],[Date]],'R DATA BNPL'!$F:$F,'REKAP PERFORMANCE'!$R$6) -> 0 | T13: =SUMIFS('R DATA BNPL'!$G:$G,'R DATA BNPL'!$E:$E,B13,'R DATA BNPL'!$F:$F,'REKAP PERFORMANCE'!$T$6) -> 0 | U13: =SUMIFS('R DATA BNPL'!$H:$H,'R DATA BNPL'!$E:$E,DAILY[[#This Row],[Date]],'R DATA BNPL'!$F:$F,'REKAP PERFORMANCE'!$T$6) -> 0 | V13: =R13+T13 -> 0 | W13: =S13+U13 -> 0 | X13: =SUMIFS('R DATA BNPL'!$G:$G,'R DATA BNPL'!$E:$E,B13,'R DATA BNPL'!$F:$F,'REKAP PERFORMANCE'!$X$6) -> 0 | Y13: =SUMIFS('R DATA BNPL'!$H:$H,'R DATA BNPL'!$E:$E,DAILY[[#This Row],[Date]],'R DATA BNPL'!$F:$F,'REKAP PERFORMANCE'!$X$6) -> 0 | Z13: =SUMIFS('R DATA BNPL'!$G:$G,'R DATA BNPL'!$E:$E,B13,'R DATA BNPL'!$F:$F,'REKAP PERFORMANCE'!$Z$6) -> 0 | AA13: =SUMIFS('R DATA BNPL'!$H:$H,'R DATA BNPL'!$E:$E,DAILY[[#This Row],[Date]],'R DATA BNPL'!$F:$F,'REKAP PERFORMANCE'!$Z$6) -> 0 | AB13: =X13+Z13 -> 0 | AC13: =Y13+AA13 -> 0 | AD13: =SUMIFS('R DATA BNPL'!$G:$G,'R DATA BNPL'!$E:$E,B13,'R DATA BNPL'!$F:$F,'REKAP PERFORMANCE'!$AD$6) -> 18163000 | AE13: =SUMIFS('R DATA BNPL'!$H:$H,'R DATA BNPL'!$E:$E,DAILY[[#This Row],[Date]],'R DATA BNPL'!$F:$F,'REKAP PERFORMANCE'!$AD$6) -> 2 | AH13: =SUMIFS('R DATA BNPL'!$G:$G,'R DATA BNPL'!$E:$E,B13,'R DATA BNPL'!$F:$F,'REKAP PERFORMANCE'!$AH$6) -> 0 | AI13: =SUMIFS('R DATA BNPL'!$G:$G,'R DATA BNPL'!$E:$E,B13,'R DATA BNPL'!$F:$F,'REKAP PERFORMANCE'!$AI$6) -> 0 | AJ13: =SUMIFS('R DATA BNPL'!$G:$G,'R DATA BNPL'!$E:$E,B13,'R DATA BNPL'!$F:$F,'REKAP PERFORMANCE'!$AJ$6) -> 0 | AM13: Total Pencapaian | AN13: =SUM(AN9:AP9) -> 537327140 | AQ13: =AQ9+AR9 -> 0 | AS13: =AS9+AT9 -> 0 | AU13: =SUM(AU9:AV9) -> 145077000 | AW13: =AW9 -> 90757000
A14: =TEXT(B14,"[$-us]dddd") -> Selasa | B14: =IF(MONTH(B13+1)=$A$4,B13+1) -> 46273 | D14: =SUMIFS('R DATA BNPL'!$G:$G,'R DATA BNPL'!$E:$E,B14,'R DATA BNPL'!$F:$F,'REKAP PERFORMANCE'!$D$6) -> 0 | E14: =SUMIFS('R DATA BNPL'!$H:$H,'R DATA BNPL'!$E:$E,DAILY[[#This Row],[Date]],'R DATA BNPL'!$F:$F,'REKAP PERFORMANCE'!$D$6) -> 0 | F14: =SUMIFS('R DATA BNPL'!$G:$G,'R DATA BNPL'!$E:$E,B14,'R DATA BNPL'!$F:$F,'REKAP PERFORMANCE'!$F$6) -> 0 | G14: =SUMIFS('R DATA BNPL'!$H:$H,'R DATA BNPL'!$E:$E,DAILY[[#This Row],[Date]],'R DATA BNPL'!$F:$F,'REKAP PERFORMANCE'!$F$6) -> 0 | H14: =SUMIFS('R DATA BNPL'!$G:$G,'R DATA BNPL'!$E:$E,B14,'R DATA BNPL'!$F:$F,'REKAP PERFORMANCE'!$H$6) -> 12524000 | I14: =SUMIFS('R DATA BNPL'!$H:$H,'R DATA BNPL'!$E:$E,DAILY[[#This Row],[Date]],'R DATA BNPL'!$F:$F,'REKAP PERFORMANCE'!$H$6) -> 1 | J14: =D14+F14+H14 -> 12524000 | K14: =E14+G14+I14 -> 1 | L14: =SUMIFS('R DATA BNPL'!$G:$G,'R DATA BNPL'!$E:$E,B14,'R DATA BNPL'!$F:$F,'REKAP PERFORMANCE'!$L$6) -> 0 | M14: =SUMIFS('R DATA BNPL'!$H:$H,'R DATA BNPL'!$E:$E,DAILY[[#This Row],[Date]],'R DATA BNPL'!$F:$F,'REKAP PERFORMANCE'!$L$6) -> 0 | N14: =SUMIFS('R DATA BNPL'!$G:$G,'R DATA BNPL'!$E:$E,B14,'R DATA BNPL'!$F:$F,'REKAP PERFORMANCE'!$N$6) -> 0 | O14: =SUMIFS('R DATA BNPL'!$H:$H,'R DATA BNPL'!$E:$E,DAILY[[#This Row],[Date]],'R DATA BNPL'!$F:$F,'REKAP PERFORMANCE'!$N$6) -> 0 | P14: =L14+N14 -> 0 | Q14: =M14+O14 -> 0 | R14: =SUMIFS('R DATA BNPL'!$G:$G,'R DATA BNPL'!$E:$E,B14,'R DATA BNPL'!$F:$F,'REKAP PERFORMANCE'!$R$6) -> 0 | S14: =SUMIFS('R DATA BNPL'!$H:$H,'R DATA BNPL'!$E:$E,DAILY[[#This Row],[Date]],'R DATA BNPL'!$F:$F,'REKAP PERFORMANCE'!$R$6) -> 0 | T14: =SUMIFS('R DATA BNPL'!$G:$G,'R DATA BNPL'!$E:$E,B14,'R DATA BNPL'!$F:$F,'REKAP PERFORMANCE'!$T$6) -> 0 | U14: =SUMIFS('R DATA BNPL'!$H:$H,'R DATA BNPL'!$E:$E,DAILY[[#This Row],[Date]],'R DATA BNPL'!$F:$F,'REKAP PERFORMANCE'!$T$6) -> 0 | V14: =R14+T14 -> 0 | W14: =S14+U14 -> 0 | X14: =SUMIFS('R DATA BNPL'!$G:$G,'R DATA BNPL'!$E:$E,B14,'R DATA BNPL'!$F:$F,'REKAP PERFORMANCE'!$X$6) -> 14009000 | Y14: =SUMIFS('R DATA BNPL'!$H:$H,'R DATA BNPL'!$E:$E,DAILY[[#This Row],[Date]],'R DATA BNPL'!$F:$F,'REKAP PERFORMANCE'!$X$6) -> 1 | Z14: =SUMIFS('R DATA BNPL'!$G:$G,'R DATA BNPL'!$E:$E,B14,'R DATA BNPL'!$F:$F,'REKAP PERFORMANCE'!$Z$6) -> 0 | AA14: =SUMIFS('R DATA BNPL'!$H:$H,'R DATA BNPL'!$E:$E,DAILY[[#This Row],[Date]],'R DATA BNPL'!$F:$F,'REKAP PERFORMANCE'!$Z$6) -> 0 | AB14: =X14+Z14 -> 14009000 | AC14: =Y14+AA14 -> 1 | AD14: =SUMIFS('R DATA BNPL'!$G:$G,'R DATA BNPL'!$E:$E,B14,'R DATA BNPL'!$F:$F,'REKAP PERFORMANCE'!$AD$6) -> 7299000 | AE14: =SUMIFS('R DATA BNPL'!$H:$H,'R DATA BNPL'!$E:$E,DAILY[[#This Row],[Date]],'R DATA BNPL'!$F:$F,'REKAP PERFORMANCE'!$AD$6) -> 1 | AH14: =SUMIFS('R DATA BNPL'!$G:$G,'R DATA BNPL'!$E:$E,B14,'R DATA BNPL'!$F:$F,'REKAP PERFORMANCE'!$AH$6) -> 0 | AI14: =SUMIFS('R DATA BNPL'!$G:$G,'R DATA BNPL'!$E:$E,B14,'R DATA BNPL'!$F:$F,'REKAP PERFORMANCE'!$AI$6) -> 0 | AJ14: =SUMIFS('R DATA BNPL'!$G:$G,'R DATA BNPL'!$E:$E,B14,'R DATA BNPL'!$F:$F,'REKAP PERFORMANCE'!$AJ$6) -> 0 | AM14: Persen To Target | AN14: 0 | AO14: 0.5 | AP14: 0.5 | AU14: 1 | AW14: 1
A15: =TEXT(B15,"[$-us]dddd") -> Rabu | B15: =IF(MONTH(B14+1)=$A$4,B14+1) -> 46274 | D15: =SUMIFS('R DATA BNPL'!$G:$G,'R DATA BNPL'!$E:$E,B15,'R DATA BNPL'!$F:$F,'REKAP PERFORMANCE'!$D$6) -> 0 | E15: =SUMIFS('R DATA BNPL'!$H:$H,'R DATA BNPL'!$E:$E,DAILY[[#This Row],[Date]],'R DATA BNPL'!$F:$F,'REKAP PERFORMANCE'!$D$6) -> 0 | F15: =SUMIFS('R DATA BNPL'!$G:$G,'R DATA BNPL'!$E:$E,B15,'R DATA BNPL'!$F:$F,'REKAP PERFORMANCE'!$F$6) -> 0 | G15: =SUMIFS('R DATA BNPL'!$H:$H,'R DATA BNPL'!$E:$E,DAILY[[#This Row],[Date]],'R DATA BNPL'!$F:$F,'REKAP PERFORMANCE'!$F$6) -> 0 | H15: =SUMIFS('R DATA BNPL'!$G:$G,'R DATA BNPL'!$E:$E,B15,'R DATA BNPL'!$F:$F,'REKAP PERFORMANCE'!$H$6) -> 0 | I15: =SUMIFS('R DATA BNPL'!$H:$H,'R DATA BNPL'!$E:$E,DAILY[[#This Row],[Date]],'R DATA BNPL'!$F:$F,'REKAP PERFORMANCE'!$H$6) -> 0 | J15: =D15+F15+H15 -> 0 | K15: =E15+G15+I15 -> 0 | L15: =SUMIFS('R DATA BNPL'!$G:$G,'R DATA BNPL'!$E:$E,B15,'R DATA BNPL'!$F:$F,'REKAP PERFORMANCE'!$L$6) -> 0 | M15: =SUMIFS('R DATA BNPL'!$H:$H,'R DATA BNPL'!$E:$E,DAILY[[#This Row],[Date]],'R DATA BNPL'!$F:$F,'REKAP PERFORMANCE'!$L$6) -> 0 | N15: =SUMIFS('R DATA BNPL'!$G:$G,'R DATA BNPL'!$E:$E,B15,'R DATA BNPL'!$F:$F,'REKAP PERFORMANCE'!$N$6) -> 0 | O15: =SUMIFS('R DATA BNPL'!$H:$H,'R DATA BNPL'!$E:$E,DAILY[[#This Row],[Date]],'R DATA BNPL'!$F:$F,'REKAP PERFORMANCE'!$N$6) -> 0 | P15: =L15+N15 -> 0 | Q15: =M15+O15 -> 0 | R15: =SUMIFS('R DATA BNPL'!$G:$G,'R DATA BNPL'!$E:$E,B15,'R DATA BNPL'!$F:$F,'REKAP PERFORMANCE'!$R$6) -> 0 | S15: =SUMIFS('R DATA BNPL'!$H:$H,'R DATA BNPL'!$E:$E,DAILY[[#This Row],[Date]],'R DATA BNPL'!$F:$F,'REKAP PERFORMANCE'!$R$6) -> 0 | T15: =SUMIFS('R DATA BNPL'!$G:$G,'R DATA BNPL'!$E:$E,B15,'R DATA BNPL'!$F:$F,'REKAP PERFORMANCE'!$T$6) -> 0 | U15: =SUMIFS('R DATA BNPL'!$H:$H,'R DATA BNPL'!$E:$E,DAILY[[#This Row],[Date]],'R DATA BNPL'!$F:$F,'REKAP PERFORMANCE'!$T$6) -> 0 | V15: =R15+T15 -> 0 | W15: =S15+U15 -> 0 | X15: =SUMIFS('R DATA BNPL'!$G:$G,'R DATA BNPL'!$E:$E,B15,'R DATA BNPL'!$F:$F,'REKAP PERFORMANCE'!$X$6) -> 0 | Y15: =SUMIFS('R DATA BNPL'!$H:$H,'R DATA BNPL'!$E:$E,DAILY[[#This Row],[Date]],'R DATA BNPL'!$F:$F,'REKAP PERFORMANCE'!$X$6) -> 0 | Z15: =SUMIFS('R DATA BNPL'!$G:$G,'R DATA BNPL'!$E:$E,B15,'R DATA BNPL'!$F:$F,'REKAP PERFORMANCE'!$Z$6) -> 0 | AA15: =SUMIFS('R DATA BNPL'!$H:$H,'R DATA BNPL'!$E:$E,DAILY[[#This Row],[Date]],'R DATA BNPL'!$F:$F,'REKAP PERFORMANCE'!$Z$6) -> 0 | AB15: =X15+Z15 -> 0 | AC15: =Y15+AA15 -> 0 | AD15: =SUMIFS('R DATA BNPL'!$G:$G,'R DATA BNPL'!$E:$E,B15,'R DATA BNPL'!$F:$F,'REKAP PERFORMANCE'!$AD$6) -> 17150000 | AE15: =SUMIFS('R DATA BNPL'!$H:$H,'R DATA BNPL'!$E:$E,DAILY[[#This Row],[Date]],'R DATA BNPL'!$F:$F,'REKAP PERFORMANCE'!$AD$6) -> 1 | AH15: =SUMIFS('R DATA BNPL'!$G:$G,'R DATA BNPL'!$E:$E,B15,'R DATA BNPL'!$F:$F,'REKAP PERFORMANCE'!$AH$6) -> 0 | AI15: =SUMIFS('R DATA BNPL'!$G:$G,'R DATA BNPL'!$E:$E,B15,'R DATA BNPL'!$F:$F,'REKAP PERFORMANCE'!$AI$6) -> 0 | AJ15: =SUMIFS('R DATA BNPL'!$G:$G,'R DATA BNPL'!$E:$E,B15,'R DATA BNPL'!$F:$F,'REKAP PERFORMANCE'!$AJ$6) -> 0 | AM15: =IFERROR(AN15/AM5,0) -> 0.28427135 | AN15: =SUM(AN13:AW13) -> 773161140
A16: =TEXT(B16,"[$-us]dddd") -> Kamis | B16: =IF(MONTH(B15+1)=$A$4,B15+1) -> 46275 | D16: =SUMIFS('R DATA BNPL'!$G:$G,'R DATA BNPL'!$E:$E,B16,'R DATA BNPL'!$F:$F,'REKAP PERFORMANCE'!$D$6) -> 0 | E16: =SUMIFS('R DATA BNPL'!$H:$H,'R DATA BNPL'!$E:$E,DAILY[[#This Row],[Date]],'R DATA BNPL'!$F:$F,'REKAP PERFORMANCE'!$D$6) -> 0 | F16: =SUMIFS('R DATA BNPL'!$G:$G,'R DATA BNPL'!$E:$E,B16,'R DATA BNPL'!$F:$F,'REKAP PERFORMANCE'!$F$6) -> 14544000 | G16: =SUMIFS('R DATA BNPL'!$H:$H,'R DATA BNPL'!$E:$E,DAILY[[#This Row],[Date]],'R DATA BNPL'!$F:$F,'REKAP PERFORMANCE'!$F$6) -> 1 | H16: =SUMIFS('R DATA BNPL'!$G:$G,'R DATA BNPL'!$E:$E,B16,'R DATA BNPL'!$F:$F,'REKAP PERFORMANCE'!$H$6) -> 0 | I16: =SUMIFS('R DATA BNPL'!$H:$H,'R DATA BNPL'!$E:$E,DAILY[[#This Row],[Date]],'R DATA BNPL'!$F:$F,'REKAP PERFORMANCE'!$H$6) -> 0 | J16: =D16+F16+H16 -> 14544000 | K16: =E16+G16+I16 -> 1 | L16: =SUMIFS('R DATA BNPL'!$G:$G,'R DATA BNPL'!$E:$E,B16,'R DATA BNPL'!$F:$F,'REKAP PERFORMANCE'!$L$6) -> 0 | M16: =SUMIFS('R DATA BNPL'!$H:$H,'R DATA BNPL'!$E:$E,DAILY[[#This Row],[Date]],'R DATA BNPL'!$F:$F,'REKAP PERFORMANCE'!$L$6) -> 0 | N16: =SUMIFS('R DATA BNPL'!$G:$G,'R DATA BNPL'!$E:$E,B16,'R DATA BNPL'!$F:$F,'REKAP PERFORMANCE'!$N$6) -> 0 | O16: =SUMIFS('R DATA BNPL'!$H:$H,'R DATA BNPL'!$E:$E,DAILY[[#This Row],[Date]],'R DATA BNPL'!$F:$F,'REKAP PERFORMANCE'!$N$6) -> 0 | P16: =L16+N16 -> 0 | Q16: =M16+O16 -> 0 | R16: =SUMIFS('R DATA BNPL'!$G:$G,'R DATA BNPL'!$E:$E,B16,'R DATA BNPL'!$F:$F,'REKAP PERFORMANCE'!$R$6) -> 0 | S16: =SUMIFS('R DATA BNPL'!$H:$H,'R DATA BNPL'!$E:$E,DAILY[[#This Row],[Date]],'R DATA BNPL'!$F:$F,'REKAP PERFORMANCE'!$R$6) -> 0 | T16: =SUMIFS('R DATA BNPL'!$G:$G,'R DATA BNPL'!$E:$E,B16,'R DATA BNPL'!$F:$F,'REKAP PERFORMANCE'!$T$6) -> 0 | U16: =SUMIFS('R DATA BNPL'!$H:$H,'R DATA BNPL'!$E:$E,DAILY[[#This Row],[Date]],'R DATA BNPL'!$F:$F,'REKAP PERFORMANCE'!$T$6) -> 0 | V16: =R16+T16 -> 0 | W16: =S16+U16 -> 0 | X16: =SUMIFS('R DATA BNPL'!$G:$G,'R DATA BNPL'!$E:$E,B16,'R DATA BNPL'!$F:$F,'REKAP PERFORMANCE'!$X$6) -> 0 | Y16: =SUMIFS('R DATA BNPL'!$H:$H,'R DATA BNPL'!$E:$E,DAILY[[#This Row],[Date]],'R DATA BNPL'!$F:$F,'REKAP PERFORMANCE'!$X$6) -> 0 | Z16: =SUMIFS('R DATA BNPL'!$G:$G,'R DATA BNPL'!$E:$E,B16,'R DATA BNPL'!$F:$F,'REKAP PERFORMANCE'!$Z$6) -> 0 | AA16: =SUMIFS('R DATA BNPL'!$H:$H,'R DATA BNPL'!$E:$E,DAILY[[#This Row],[Date]],'R DATA BNPL'!$F:$F,'REKAP PERFORMANCE'!$Z$6) -> 0 | AB16: =X16+Z16 -> 0 | AC16: =Y16+AA16 -> 0 | AD16: =SUMIFS('R DATA BNPL'!$G:$G,'R DATA BNPL'!$E:$E,B16,'R DATA BNPL'!$F:$F,'REKAP PERFORMANCE'!$AD$6) -> 13397000 | AE16: =SUMIFS('R DATA BNPL'!$H:$H,'R DATA BNPL'!$E:$E,DAILY[[#This Row],[Date]],'R DATA BNPL'!$F:$F,'REKAP PERFORMANCE'!$AD$6) -> 1 | AH16: =SUMIFS('R DATA BNPL'!$G:$G,'R DATA BNPL'!$E:$E,B16,'R DATA BNPL'!$F:$F,'REKAP PERFORMANCE'!$AH$6) -> 0 | AI16: =SUMIFS('R DATA BNPL'!$G:$G,'R DATA BNPL'!$E:$E,B16,'R DATA BNPL'!$F:$F,'REKAP PERFORMANCE'!$AI$6) -> 0 | AJ16: =SUMIFS('R DATA BNPL'!$G:$G,'R DATA BNPL'!$E:$E,B16,'R DATA BNPL'!$F:$F,'REKAP PERFORMANCE'!$AJ$6) -> 0
A17: =TEXT(B17,"[$-us]dddd") -> Jumat | B17: =IF(MONTH(B16+1)=$A$4,B16+1) -> 46276 | D17: =SUMIFS('R DATA BNPL'!$G:$G,'R DATA BNPL'!$E:$E,B17,'R DATA BNPL'!$F:$F,'REKAP PERFORMANCE'!$D$6) -> 0 | E17: =SUMIFS('R DATA BNPL'!$H:$H,'R DATA BNPL'!$E:$E,DAILY[[#This Row],[Date]],'R DATA BNPL'!$F:$F,'REKAP PERFORMANCE'!$D$6) -> 0 | F17: =SUMIFS('R DATA BNPL'!$G:$G,'R DATA BNPL'!$E:$E,B17,'R DATA BNPL'!$F:$F,'REKAP PERFORMANCE'!$F$6) -> 0 | G17: =SUMIFS('R DATA BNPL'!$H:$H,'R DATA BNPL'!$E:$E,DAILY[[#This Row],[Date]],'R DATA BNPL'!$F:$F,'REKAP PERFORMANCE'!$F$6) -> 0 | H17: =SUMIFS('R DATA BNPL'!$G:$G,'R DATA BNPL'!$E:$E,B17,'R DATA BNPL'!$F:$F,'REKAP PERFORMANCE'!$H$6) -> 11817000 | I17: =SUMIFS('R DATA BNPL'!$H:$H,'R DATA BNPL'!$E:$E,DAILY[[#This Row],[Date]],'R DATA BNPL'!$F:$F,'REKAP PERFORMANCE'!$H$6) -> 1 | J17: =D17+F17+H17 -> 11817000 | K17: =E17+G17+I17 -> 1 | L17: =SUMIFS('R DATA BNPL'!$G:$G,'R DATA BNPL'!$E:$E,B17,'R DATA BNPL'!$F:$F,'REKAP PERFORMANCE'!$L$6) -> 0 | M17: =SUMIFS('R DATA BNPL'!$H:$H,'R DATA BNPL'!$E:$E,DAILY[[#This Row],[Date]],'R DATA BNPL'!$F:$F,'REKAP PERFORMANCE'!$L$6) -> 0 | N17: =SUMIFS('R DATA BNPL'!$G:$G,'R DATA BNPL'!$E:$E,B17,'R DATA BNPL'!$F:$F,'REKAP PERFORMANCE'!$N$6) -> 0 | O17: =SUMIFS('R DATA BNPL'!$H:$H,'R DATA BNPL'!$E:$E,DAILY[[#This Row],[Date]],'R DATA BNPL'!$F:$F,'REKAP PERFORMANCE'!$N$6) -> 0 | P17: =L17+N17 -> 0 | Q17: =M17+O17 -> 0 | R17: =SUMIFS('R DATA BNPL'!$G:$G,'R DATA BNPL'!$E:$E,B17,'R DATA BNPL'!$F:$F,'REKAP PERFORMANCE'!$R$6) -> 0 | S17: =SUMIFS('R DATA BNPL'!$H:$H,'R DATA BNPL'!$E:$E,DAILY[[#This Row],[Date]],'R DATA BNPL'!$F:$F,'REKAP PERFORMANCE'!$R$6) -> 0 | T17: =SUMIFS('R DATA BNPL'!$G:$G,'R DATA BNPL'!$E:$E,B17,'R DATA BNPL'!$F:$F,'REKAP PERFORMANCE'!$T$6) -> 0 | U17: =SUMIFS('R DATA BNPL'!$H:$H,'R DATA BNPL'!$E:$E,DAILY[[#This Row],[Date]],'R DATA BNPL'!$F:$F,'REKAP PERFORMANCE'!$T$6) -> 0 | V17: =R17+T17 -> 0 | W17: =S17+U17 -> 0 | X17: =SUMIFS('R DATA BNPL'!$G:$G,'R DATA BNPL'!$E:$E,B17,'R DATA BNPL'!$F:$F,'REKAP PERFORMANCE'!$X$6) -> 0 | Y17: =SUMIFS('R DATA BNPL'!$H:$H,'R DATA BNPL'!$E:$E,DAILY[[#This Row],[Date]],'R DATA BNPL'!$F:$F,'REKAP PERFORMANCE'!$X$6) -> 0 | Z17: =SUMIFS('R DATA BNPL'!$G:$G,'R DATA BNPL'!$E:$E,B17,'R DATA BNPL'!$F:$F,'REKAP PERFORMANCE'!$Z$6) -> 0 | AA17: =SUMIFS('R DATA BNPL'!$H:$H,'R DATA BNPL'!$E:$E,DAILY[[#This Row],[Date]],'R DATA BNPL'!$F:$F,'REKAP PERFORMANCE'!$Z$6) -> 0 | AB17: =X17+Z17 -> 0 | AC17: =Y17+AA17 -> 0 | AD17: =SUMIFS('R DATA BNPL'!$G:$G,'R DATA BNPL'!$E:$E,B17,'R DATA BNPL'!$F:$F,'REKAP PERFORMANCE'!$AD$6) -> 0 | AE17: =SUMIFS('R DATA BNPL'!$H:$H,'R DATA BNPL'!$E:$E,DAILY[[#This Row],[Date]],'R DATA BNPL'!$F:$F,'REKAP PERFORMANCE'!$AD$6) -> 0 | AH17: =SUMIFS('R DATA BNPL'!$G:$G,'R DATA BNPL'!$E:$E,B17,'R DATA BNPL'!$F:$F,'REKAP PERFORMANCE'!$AH$6) -> 0 | AI17: =SUMIFS('R DATA BNPL'!$G:$G,'R DATA BNPL'!$E:$E,B17,'R DATA BNPL'!$F:$F,'REKAP PERFORMANCE'!$AI$6) -> 0 | AJ17: =SUMIFS('R DATA BNPL'!$G:$G,'R DATA BNPL'!$E:$E,B17,'R DATA BNPL'!$F:$F,'REKAP PERFORMANCE'!$AJ$6) -> 0 | AM17: Laku 6
A18: =TEXT(B18,"[$-us]dddd") -> Sabtu | B18: =IF(MONTH(B17+1)=$A$4,B17+1) -> 46277 | D18: =SUMIFS('R DATA BNPL'!$G:$G,'R DATA BNPL'!$E:$E,B18,'R DATA BNPL'!$F:$F,'REKAP PERFORMANCE'!$D$6) -> 0 | E18: =SUMIFS('R DATA BNPL'!$H:$H,'R DATA BNPL'!$E:$E,DAILY[[#This Row],[Date]],'R DATA BNPL'!$F:$F,'REKAP PERFORMANCE'!$D$6) -> 0 | F18: =SUMIFS('R DATA BNPL'!$G:$G,'R DATA BNPL'!$E:$E,B18,'R DATA BNPL'!$F:$F,'REKAP PERFORMANCE'!$F$6) -> 50900970 | G18: =SUMIFS('R DATA BNPL'!$H:$H,'R DATA BNPL'!$E:$E,DAILY[[#This Row],[Date]],'R DATA BNPL'!$F:$F,'REKAP PERFORMANCE'!$F$6) -> 2 | H18: =SUMIFS('R DATA BNPL'!$G:$G,'R DATA BNPL'!$E:$E,B18,'R DATA BNPL'!$F:$F,'REKAP PERFORMANCE'!$H$6) -> 574690 | I18: =SUMIFS('R DATA BNPL'!$H:$H,'R DATA BNPL'!$E:$E,DAILY[[#This Row],[Date]],'R DATA BNPL'!$F:$F,'REKAP PERFORMANCE'!$H$6) -> 1 | J18: =D18+F18+H18 -> 51475660 | K18: =E18+G18+I18 -> 3 | L18: =SUMIFS('R DATA BNPL'!$G:$G,'R DATA BNPL'!$E:$E,B18,'R DATA BNPL'!$F:$F,'REKAP PERFORMANCE'!$L$6) -> 0 | M18: =SUMIFS('R DATA BNPL'!$H:$H,'R DATA BNPL'!$E:$E,DAILY[[#This Row],[Date]],'R DATA BNPL'!$F:$F,'REKAP PERFORMANCE'!$L$6) -> 0 | N18: =SUMIFS('R DATA BNPL'!$G:$G,'R DATA BNPL'!$E:$E,B18,'R DATA BNPL'!$F:$F,'REKAP PERFORMANCE'!$N$6) -> 0 | O18: =SUMIFS('R DATA BNPL'!$H:$H,'R DATA BNPL'!$E:$E,DAILY[[#This Row],[Date]],'R DATA BNPL'!$F:$F,'REKAP PERFORMANCE'!$N$6) -> 0 | P18: =L18+N18 -> 0 | Q18: =M18+O18 -> 0 | R18: =SUMIFS('R DATA BNPL'!$G:$G,'R DATA BNPL'!$E:$E,B18,'R DATA BNPL'!$F:$F,'REKAP PERFORMANCE'!$R$6) -> 0 | S18: =SUMIFS('R DATA BNPL'!$H:$H,'R DATA BNPL'!$E:$E,DAILY[[#This Row],[Date]],'R DATA BNPL'!$F:$F,'REKAP PERFORMANCE'!$R$6) -> 0 | T18: =SUMIFS('R DATA BNPL'!$G:$G,'R DATA BNPL'!$E:$E,B18,'R DATA BNPL'!$F:$F,'REKAP PERFORMANCE'!$T$6) -> 0 | U18: =SUMIFS('R DATA BNPL'!$H:$H,'R DATA BNPL'!$E:$E,DAILY[[#This Row],[Date]],'R DATA BNPL'!$F:$F,'REKAP PERFORMANCE'!$T$6) -> 0 | V18: =R18+T18 -> 0 | W18: =S18+U18 -> 0 | X18: =SUMIFS('R DATA BNPL'!$G:$G,'R DATA BNPL'!$E:$E,B18,'R DATA BNPL'!$F:$F,'REKAP PERFORMANCE'!$X$6) -> 14314000 | Y18: =SUMIFS('R DATA BNPL'!$H:$H,'R DATA BNPL'!$E:$E,DAILY[[#This Row],[Date]],'R DATA BNPL'!$F:$F,'REKAP PERFORMANCE'!$X$6) -> 1 | Z18: =SUMIFS('R DATA BNPL'!$G:$G,'R DATA BNPL'!$E:$E,B18,'R DATA BNPL'!$F:$F,'REKAP PERFORMANCE'!$Z$6) -> 0 | AA18: =SUMIFS('R DATA BNPL'!$H:$H,'R DATA BNPL'!$E:$E,DAILY[[#This Row],[Date]],'R DATA BNPL'!$F:$F,'REKAP PERFORMANCE'!$Z$6) -> 0 | AB18: =X18+Z18 -> 14314000 | AC18: =Y18+AA18 -> 1 | AD18: =SUMIFS('R DATA BNPL'!$G:$G,'R DATA BNPL'!$E:$E,B18,'R DATA BNPL'!$F:$F,'REKAP PERFORMANCE'!$AD$6) -> 0 | AE18: =SUMIFS('R DATA BNPL'!$H:$H,'R DATA BNPL'!$E:$E,DAILY[[#This Row],[Date]],'R DATA BNPL'!$F:$F,'REKAP PERFORMANCE'!$AD$6) -> 0 | AH18: =SUMIFS('R DATA BNPL'!$G:$G,'R DATA BNPL'!$E:$E,B18,'R DATA BNPL'!$F:$F,'REKAP PERFORMANCE'!$AH$6) -> 0 | AI18: =SUMIFS('R DATA BNPL'!$G:$G,'R DATA BNPL'!$E:$E,B18,'R DATA BNPL'!$F:$F,'REKAP PERFORMANCE'!$AI$6) -> 0 | AJ18: =SUMIFS('R DATA BNPL'!$G:$G,'R DATA BNPL'!$E:$E,B18,'R DATA BNPL'!$F:$F,'REKAP PERFORMANCE'!$AJ$6) -> 0 | AM18: Tier 0 | AN18: Tier 1 | AO18: Tier 2 | AP18: Tier 3
A19: =TEXT(B19,"[$-us]dddd") -> Minggu | B19: =IF(MONTH(B18+1)=$A$4,B18+1) -> 46278 | D19: =SUMIFS('R DATA BNPL'!$G:$G,'R DATA BNPL'!$E:$E,B19,'R DATA BNPL'!$F:$F,'REKAP PERFORMANCE'!$D$6) -> 0 | E19: =SUMIFS('R DATA BNPL'!$H:$H,'R DATA BNPL'!$E:$E,DAILY[[#This Row],[Date]],'R DATA BNPL'!$F:$F,'REKAP PERFORMANCE'!$D$6) -> 0 | F19: =SUMIFS('R DATA BNPL'!$G:$G,'R DATA BNPL'!$E:$E,B19,'R DATA BNPL'!$F:$F,'REKAP PERFORMANCE'!$F$6) -> 0 | G19: =SUMIFS('R DATA BNPL'!$H:$H,'R DATA BNPL'!$E:$E,DAILY[[#This Row],[Date]],'R DATA BNPL'!$F:$F,'REKAP PERFORMANCE'!$F$6) -> 0 | H19: =SUMIFS('R DATA BNPL'!$G:$G,'R DATA BNPL'!$E:$E,B19,'R DATA BNPL'!$F:$F,'REKAP PERFORMANCE'!$H$6) -> 39354000 | I19: =SUMIFS('R DATA BNPL'!$H:$H,'R DATA BNPL'!$E:$E,DAILY[[#This Row],[Date]],'R DATA BNPL'!$F:$F,'REKAP PERFORMANCE'!$H$6) -> 3 | J19: =D19+F19+H19 -> 39354000 | K19: =E19+G19+I19 -> 3 | L19: =SUMIFS('R DATA BNPL'!$G:$G,'R DATA BNPL'!$E:$E,B19,'R DATA BNPL'!$F:$F,'REKAP PERFORMANCE'!$L$6) -> 0 | M19: =SUMIFS('R DATA BNPL'!$H:$H,'R DATA BNPL'!$E:$E,DAILY[[#This Row],[Date]],'R DATA BNPL'!$F:$F,'REKAP PERFORMANCE'!$L$6) -> 0 | N19: =SUMIFS('R DATA BNPL'!$G:$G,'R DATA BNPL'!$E:$E,B19,'R DATA BNPL'!$F:$F,'REKAP PERFORMANCE'!$N$6) -> 0 | O19: =SUMIFS('R DATA BNPL'!$H:$H,'R DATA BNPL'!$E:$E,DAILY[[#This Row],[Date]],'R DATA BNPL'!$F:$F,'REKAP PERFORMANCE'!$N$6) -> 0 | P19: =L19+N19 -> 0 | Q19: =M19+O19 -> 0 | R19: =SUMIFS('R DATA BNPL'!$G:$G,'R DATA BNPL'!$E:$E,B19,'R DATA BNPL'!$F:$F,'REKAP PERFORMANCE'!$R$6) -> 0 | S19: =SUMIFS('R DATA BNPL'!$H:$H,'R DATA BNPL'!$E:$E,DAILY[[#This Row],[Date]],'R DATA BNPL'!$F:$F,'REKAP PERFORMANCE'!$R$6) -> 0 | T19: =SUMIFS('R DATA BNPL'!$G:$G,'R DATA BNPL'!$E:$E,B19,'R DATA BNPL'!$F:$F,'REKAP PERFORMANCE'!$T$6) -> 0 | U19: =SUMIFS('R DATA BNPL'!$H:$H,'R DATA BNPL'!$E:$E,DAILY[[#This Row],[Date]],'R DATA BNPL'!$F:$F,'REKAP PERFORMANCE'!$T$6) -> 0 | V19: =R19+T19 -> 0 | W19: =S19+U19 -> 0 | X19: =SUMIFS('R DATA BNPL'!$G:$G,'R DATA BNPL'!$E:$E,B19,'R DATA BNPL'!$F:$F,'REKAP PERFORMANCE'!$X$6) -> 21047000 | Y19: =SUMIFS('R DATA BNPL'!$H:$H,'R DATA BNPL'!$E:$E,DAILY[[#This Row],[Date]],'R DATA BNPL'!$F:$F,'REKAP PERFORMANCE'!$X$6) -> 2 | Z19: =SUMIFS('R DATA BNPL'!$G:$G,'R DATA BNPL'!$E:$E,B19,'R DATA BNPL'!$F:$F,'REKAP PERFORMANCE'!$Z$6) -> 0 | AA19: =SUMIFS('R DATA BNPL'!$H:$H,'R DATA BNPL'!$E:$E,DAILY[[#This Row],[Date]],'R DATA BNPL'!$F:$F,'REKAP PERFORMANCE'!$Z$6) -> 0 | AB19: =X19+Z19 -> 21047000 | AC19: =Y19+AA19 -> 2 | AD19: =SUMIFS('R DATA BNPL'!$G:$G,'R DATA BNPL'!$E:$E,B19,'R DATA BNPL'!$F:$F,'REKAP PERFORMANCE'!$AD$6) -> 0 | AE19: =SUMIFS('R DATA BNPL'!$H:$H,'R DATA BNPL'!$E:$E,DAILY[[#This Row],[Date]],'R DATA BNPL'!$F:$F,'REKAP PERFORMANCE'!$AD$6) -> 0 | AH19: =SUMIFS('R DATA BNPL'!$G:$G,'R DATA BNPL'!$E:$E,B19,'R DATA BNPL'!$F:$F,'REKAP PERFORMANCE'!$AH$6) -> 0 | AI19: =SUMIFS('R DATA BNPL'!$G:$G,'R DATA BNPL'!$E:$E,B19,'R DATA BNPL'!$F:$F,'REKAP PERFORMANCE'!$AI$6) -> 0 | AJ19: =SUMIFS('R DATA BNPL'!$G:$G,'R DATA BNPL'!$E:$E,B19,'R DATA BNPL'!$F:$F,'REKAP PERFORMANCE'!$AJ$6) -> 0 | AL19: Rahman Ibrahim | AM19: =SUMIFS('R DATA BNPL'!$H:$H, 'R DATA BNPL'!$F:$F, 'REKAP PERFORMANCE'!AL19, 'R DATA BNPL'!$I:$I, 'REKAP PERFORMANCE'!$AM$18, 'R DATA BNPL'!$D:$D, 'REKAP PERFORMANCE'!$AM$17, 'R DATA BNPL'!$E:$E, ">="&DATE('REKAP PERFORMANCE'!$A$1, 'REKAP PERFORMANCE'!$A$4, 1), 'R DATA BNPL'!$E:$E, "<="&EOMONTH(DATE('REKAP PERFORMANCE'!$A$1, 'REKAP PERFORMANCE'!$A$4, 1), 0)) -> 0 | AN19: =SUMIFS('R DATA BNPL'!$H:$H, 'R DATA BNPL'!$F:$F, 'REKAP PERFORMANCE'!AL19, 'R DATA BNPL'!$I:$I, 'REKAP PERFORMANCE'!$AN$18, 'R DATA BNPL'!$D:$D, 'REKAP PERFORMANCE'!$AM$17, 'R DATA BNPL'!$E:$E, ">="&DATE('REKAP PERFORMANCE'!$A$1, 'REKAP PERFORMANCE'!$A$4, 1), 'R DATA BNPL'!$E:$E, "<="&EOMONTH(DATE('REKAP PERFORMANCE'!$A$1, 'REKAP PERFORMANCE'!$A$4, 1), 0)) -> 0 | AO19: =SUMIFS('R DATA BNPL'!$H:$H, 'R DATA BNPL'!$F:$F, 'REKAP PERFORMANCE'!AL19, 'R DATA BNPL'!$I:$I, 'REKAP PERFORMANCE'!$AO$18, 'R DATA BNPL'!$D:$D, 'REKAP PERFORMANCE'!$AM$17, 'R DATA BNPL'!$E:$E, ">="&DATE('REKAP PERFORMANCE'!$A$1, 'REKAP PERFORMANCE'!$A$4, 1), 'R DATA BNPL'!$E:$E, "<="&EOMONTH(DATE('REKAP PERFORMANCE'!$A$1, 'REKAP PERFORMANCE'!$A$4, 1), 0)) -> 0 | AP19: =SUMIFS('R DATA BNPL'!$H:$H, 'R DATA BNPL'!$F:$F, 'REKAP PERFORMANCE'!AL19, 'R DATA BNPL'!$I:$I, 'REKAP PERFORMANCE'!$AP$18, 'R DATA BNPL'!$D:$D, 'REKAP PERFORMANCE'!$AM$17, 'R DATA BNPL'!$E:$E, ">="&DATE('REKAP PERFORMANCE'!$A$1, 'REKAP PERFORMANCE'!$A$4, 1), 'R DATA BNPL'!$E:$E, "<="&EOMONTH(DATE('REKAP PERFORMANCE'!$A$1, 'REKAP PERFORMANCE'!$A$4, 1), 0)) -> 0
A20: =TEXT(B20,"[$-us]dddd") -> Senin | B20: =IF(MONTH(B19+1)=$A$4,B19+1) -> 46279 | D20: =SUMIFS('R DATA BNPL'!$G:$G,'R DATA BNPL'!$E:$E,B20,'R DATA BNPL'!$F:$F,'REKAP PERFORMANCE'!$D$6) -> 0 | E20: =SUMIFS('R DATA BNPL'!$H:$H,'R DATA BNPL'!$E:$E,DAILY[[#This Row],[Date]],'R DATA BNPL'!$F:$F,'REKAP PERFORMANCE'!$D$6) -> 0 | F20: =SUMIFS('R DATA BNPL'!$G:$G,'R DATA BNPL'!$E:$E,B20,'R DATA BNPL'!$F:$F,'REKAP PERFORMANCE'!$F$6) -> 14594500 | G20: =SUMIFS('R DATA BNPL'!$H:$H,'R DATA BNPL'!$E:$E,DAILY[[#This Row],[Date]],'R DATA BNPL'!$F:$F,'REKAP PERFORMANCE'!$F$6) -> 1 | H20: =SUMIFS('R DATA BNPL'!$G:$G,'R DATA BNPL'!$E:$E,B20,'R DATA BNPL'!$F:$F,'REKAP PERFORMANCE'!$H$6) -> 13500000 | I20: =SUMIFS('R DATA BNPL'!$H:$H,'R DATA BNPL'!$E:$E,DAILY[[#This Row],[Date]],'R DATA BNPL'!$F:$F,'REKAP PERFORMANCE'!$H$6) -> 1 | J20: =D20+F20+H20 -> 28094500 | K20: =E20+G20+I20 -> 2 | L20: =SUMIFS('R DATA BNPL'!$G:$G,'R DATA BNPL'!$E:$E,B20,'R DATA BNPL'!$F:$F,'REKAP PERFORMANCE'!$L$6) -> 0 | M20: =SUMIFS('R DATA BNPL'!$H:$H,'R DATA BNPL'!$E:$E,DAILY[[#This Row],[Date]],'R DATA BNPL'!$F:$F,'REKAP PERFORMANCE'!$L$6) -> 0 | N20: =SUMIFS('R DATA BNPL'!$G:$G,'R DATA BNPL'!$E:$E,B20,'R DATA BNPL'!$F:$F,'REKAP PERFORMANCE'!$N$6) -> 0 | O20: =SUMIFS('R DATA BNPL'!$H:$H,'R DATA BNPL'!$E:$E,DAILY[[#This Row],[Date]],'R DATA BNPL'!$F:$F,'REKAP PERFORMANCE'!$N$6) -> 0 | P20: =L20+N20 -> 0 | Q20: =M20+O20 -> 0 | R20: =SUMIFS('R DATA BNPL'!$G:$G,'R DATA BNPL'!$E:$E,B20,'R DATA BNPL'!$F:$F,'REKAP PERFORMANCE'!$R$6) -> 0 | S20: =SUMIFS('R DATA BNPL'!$H:$H,'R DATA BNPL'!$E:$E,DAILY[[#This Row],[Date]],'R DATA BNPL'!$F:$F,'REKAP PERFORMANCE'!$R$6) -> 0 | T20: =SUMIFS('R DATA BNPL'!$G:$G,'R DATA BNPL'!$E:$E,B20,'R DATA BNPL'!$F:$F,'REKAP PERFORMANCE'!$T$6) -> 0 | U20: =SUMIFS('R DATA BNPL'!$H:$H,'R DATA BNPL'!$E:$E,DAILY[[#This Row],[Date]],'R DATA BNPL'!$F:$F,'REKAP PERFORMANCE'!$T$6) -> 0 | V20: =R20+T20 -> 0 | W20: =S20+U20 -> 0 | X20: =SUMIFS('R DATA BNPL'!$G:$G,'R DATA BNPL'!$E:$E,B20,'R DATA BNPL'!$F:$F,'REKAP PERFORMANCE'!$X$6) -> 20868000 | Y20: =SUMIFS('R DATA BNPL'!$H:$H,'R DATA BNPL'!$E:$E,DAILY[[#This Row],[Date]],'R DATA BNPL'!$F:$F,'REKAP PERFORMANCE'!$X$6) -> 2 | Z20: =SUMIFS('R DATA BNPL'!$G:$G,'R DATA BNPL'!$E:$E,B20,'R DATA BNPL'!$F:$F,'REKAP PERFORMANCE'!$Z$6) -> 0 | AA20: =SUMIFS('R DATA BNPL'!$H:$H,'R DATA BNPL'!$E:$E,DAILY[[#This Row],[Date]],'R DATA BNPL'!$F:$F,'REKAP PERFORMANCE'!$Z$6) -> 0 | AB20: =X20+Z20 -> 20868000 | AC20: =Y20+AA20 -> 2 | AD20: =SUMIFS('R DATA BNPL'!$G:$G,'R DATA BNPL'!$E:$E,B20,'R DATA BNPL'!$F:$F,'REKAP PERFORMANCE'!$AD$6) -> 0 | AE20: =SUMIFS('R DATA BNPL'!$H:$H,'R DATA BNPL'!$E:$E,DAILY[[#This Row],[Date]],'R DATA BNPL'!$F:$F,'REKAP PERFORMANCE'!$AD$6) -> 0 | AH20: =SUMIFS('R DATA BNPL'!$G:$G,'R DATA BNPL'!$E:$E,B20,'R DATA BNPL'!$F:$F,'REKAP PERFORMANCE'!$AH$6) -> 0 | AI20: =SUMIFS('R DATA BNPL'!$G:$G,'R DATA BNPL'!$E:$E,B20,'R DATA BNPL'!$F:$F,'REKAP PERFORMANCE'!$AI$6) -> 0 | AJ20: =SUMIFS('R DATA BNPL'!$G:$G,'R DATA BNPL'!$E:$E,B20,'R DATA BNPL'!$F:$F,'REKAP PERFORMANCE'!$AJ$6) -> 0 | AL20: Virginia Bella | AM20: =SUMIFS('R DATA BNPL'!$H:$H, 'R DATA BNPL'!$F:$F, 'REKAP PERFORMANCE'!AL20, 'R DATA BNPL'!$I:$I, 'REKAP PERFORMANCE'!$AM$18, 'R DATA BNPL'!$D:$D, 'REKAP PERFORMANCE'!$AM$17, 'R DATA BNPL'!$E:$E, ">="&DATE('REKAP PERFORMANCE'!$A$1, 'REKAP PERFORMANCE'!$A$4, 1), 'R DATA BNPL'!$E:$E, "<="&EOMONTH(DATE('REKAP PERFORMANCE'!$A$1, 'REKAP PERFORMANCE'!$A$4, 1), 0)) -> 0 | AN20: =SUMIFS('R DATA BNPL'!$H:$H, 'R DATA BNPL'!$F:$F, 'REKAP PERFORMANCE'!AL20, 'R DATA BNPL'!$I:$I, 'REKAP PERFORMANCE'!$AN$18, 'R DATA BNPL'!$D:$D, 'REKAP PERFORMANCE'!$AM$17, 'R DATA BNPL'!$E:$E, ">="&DATE('REKAP PERFORMANCE'!$A$1, 'REKAP PERFORMANCE'!$A$4, 1), 'R DATA BNPL'!$E:$E, "<="&EOMONTH(DATE('REKAP PERFORMANCE'!$A$1, 'REKAP PERFORMANCE'!$A$4, 1), 0)) -> 0 | AO20: =SUMIFS('R DATA BNPL'!$H:$H, 'R DATA BNPL'!$F:$F, 'REKAP PERFORMANCE'!AL20, 'R DATA BNPL'!$I:$I, 'REKAP PERFORMANCE'!$AO$18, 'R DATA BNPL'!$D:$D, 'REKAP PERFORMANCE'!$AM$17, 'R DATA BNPL'!$E:$E, ">="&DATE('REKAP PERFORMANCE'!$A$1, 'REKAP PERFORMANCE'!$A$4, 1), 'R DATA BNPL'!$E:$E, "<="&EOMONTH(DATE('REKAP PERFORMANCE'!$A$1, 'REKAP PERFORMANCE'!$A$4, 1), 0)) -> 0 | AP20: =SUMIFS('R DATA BNPL'!$H:$H, 'R DATA BNPL'!$F:$F, 'REKAP PERFORMANCE'!AL20, 'R DATA BNPL'!$I:$I, 'REKAP PERFORMANCE'!$AP$18, 'R DATA BNPL'!$D:$D, 'REKAP PERFORMANCE'!$AM$17, 'R DATA BNPL'!$E:$E, ">="&DATE('REKAP PERFORMANCE'!$A$1, 'REKAP PERFORMANCE'!$A$4, 1), 'R DATA BNPL'!$E:$E, "<="&EOMONTH(DATE('REKAP PERFORMANCE'!$A$1, 'REKAP PERFORMANCE'!$A$4, 1), 0)) -> 0
A21: =TEXT(B21,"[$-us]dddd") -> Selasa | B21: =IF(MONTH(B20+1)=$A$4,B20+1) -> 46280 | D21: =SUMIFS('R DATA BNPL'!$G:$G,'R DATA BNPL'!$E:$E,B21,'R DATA BNPL'!$F:$F,'REKAP PERFORMANCE'!$D$6) -> 0 | E21: =SUMIFS('R DATA BNPL'!$H:$H,'R DATA BNPL'!$E:$E,DAILY[[#This Row],[Date]],'R DATA BNPL'!$F:$F,'REKAP PERFORMANCE'!$D$6) -> 0 | F21: =SUMIFS('R DATA BNPL'!$G:$G,'R DATA BNPL'!$E:$E,B21,'R DATA BNPL'!$F:$F,'REKAP PERFORMANCE'!$F$6) -> 0 | G21: =SUMIFS('R DATA BNPL'!$H:$H,'R DATA BNPL'!$E:$E,DAILY[[#This Row],[Date]],'R DATA BNPL'!$F:$F,'REKAP PERFORMANCE'!$F$6) -> 0 | H21: =SUMIFS('R DATA BNPL'!$G:$G,'R DATA BNPL'!$E:$E,B21,'R DATA BNPL'!$F:$F,'REKAP PERFORMANCE'!$H$6) -> 52911880 | I21: =SUMIFS('R DATA BNPL'!$H:$H,'R DATA BNPL'!$E:$E,DAILY[[#This Row],[Date]],'R DATA BNPL'!$F:$F,'REKAP PERFORMANCE'!$H$6) -> 2 | J21: =D21+F21+H21 -> 52911880 | K21: =E21+G21+I21 -> 2 | L21: =SUMIFS('R DATA BNPL'!$G:$G,'R DATA BNPL'!$E:$E,B21,'R DATA BNPL'!$F:$F,'REKAP PERFORMANCE'!$L$6) -> 0 | M21: =SUMIFS('R DATA BNPL'!$H:$H,'R DATA BNPL'!$E:$E,DAILY[[#This Row],[Date]],'R DATA BNPL'!$F:$F,'REKAP PERFORMANCE'!$L$6) -> 0 | N21: =SUMIFS('R DATA BNPL'!$G:$G,'R DATA BNPL'!$E:$E,B21,'R DATA BNPL'!$F:$F,'REKAP PERFORMANCE'!$N$6) -> 0 | O21: =SUMIFS('R DATA BNPL'!$H:$H,'R DATA BNPL'!$E:$E,DAILY[[#This Row],[Date]],'R DATA BNPL'!$F:$F,'REKAP PERFORMANCE'!$N$6) -> 0 | P21: =L21+N21 -> 0 | Q21: =M21+O21 -> 0 | R21: =SUMIFS('R DATA BNPL'!$G:$G,'R DATA BNPL'!$E:$E,B21,'R DATA BNPL'!$F:$F,'REKAP PERFORMANCE'!$R$6) -> 0 | S21: =SUMIFS('R DATA BNPL'!$H:$H,'R DATA BNPL'!$E:$E,DAILY[[#This Row],[Date]],'R DATA BNPL'!$F:$F,'REKAP PERFORMANCE'!$R$6) -> 0 | T21: =SUMIFS('R DATA BNPL'!$G:$G,'R DATA BNPL'!$E:$E,B21,'R DATA BNPL'!$F:$F,'REKAP PERFORMANCE'!$T$6) -> 0 | U21: =SUMIFS('R DATA BNPL'!$H:$H,'R DATA BNPL'!$E:$E,DAILY[[#This Row],[Date]],'R DATA BNPL'!$F:$F,'REKAP PERFORMANCE'!$T$6) -> 0 | V21: =R21+T21 -> 0 | W21: =S21+U21 -> 0 | X21: =SUMIFS('R DATA BNPL'!$G:$G,'R DATA BNPL'!$E:$E,B21,'R DATA BNPL'!$F:$F,'REKAP PERFORMANCE'!$X$6) -> 17313000 | Y21: =SUMIFS('R DATA BNPL'!$H:$H,'R DATA BNPL'!$E:$E,DAILY[[#This Row],[Date]],'R DATA BNPL'!$F:$F,'REKAP PERFORMANCE'!$X$6) -> 1 | Z21: =SUMIFS('R DATA BNPL'!$G:$G,'R DATA BNPL'!$E:$E,B21,'R DATA BNPL'!$F:$F,'REKAP PERFORMANCE'!$Z$6) -> 0 | AA21: =SUMIFS('R DATA BNPL'!$H:$H,'R DATA BNPL'!$E:$E,DAILY[[#This Row],[Date]],'R DATA BNPL'!$F:$F,'REKAP PERFORMANCE'!$Z$6) -> 0 | AB21: =X21+Z21 -> 17313000 | AC21: =Y21+AA21 -> 1 | AD21: =SUMIFS('R DATA BNPL'!$G:$G,'R DATA BNPL'!$E:$E,B21,'R DATA BNPL'!$F:$F,'REKAP PERFORMANCE'!$AD$6) -> 0 | AE21: =SUMIFS('R DATA BNPL'!$H:$H,'R DATA BNPL'!$E:$E,DAILY[[#This Row],[Date]],'R DATA BNPL'!$F:$F,'REKAP PERFORMANCE'!$AD$6) -> 0 | AH21: =SUMIFS('R DATA BNPL'!$G:$G,'R DATA BNPL'!$E:$E,B21,'R DATA BNPL'!$F:$F,'REKAP PERFORMANCE'!$AH$6) -> 0 | AI21: =SUMIFS('R DATA BNPL'!$G:$G,'R DATA BNPL'!$E:$E,B21,'R DATA BNPL'!$F:$F,'REKAP PERFORMANCE'!$AI$6) -> 0 | AJ21: =SUMIFS('R DATA BNPL'!$G:$G,'R DATA BNPL'!$E:$E,B21,'R DATA BNPL'!$F:$F,'REKAP PERFORMANCE'!$AJ$6) -> 0 | AL21: Daniela Karin | AM21: =SUMIFS('R DATA BNPL'!$H:$H, 'R DATA BNPL'!$F:$F, 'REKAP PERFORMANCE'!AL21, 'R DATA BNPL'!$I:$I, 'REKAP PERFORMANCE'!$AM$18, 'R DATA BNPL'!$D:$D, 'REKAP PERFORMANCE'!$AM$17, 'R DATA BNPL'!$E:$E, ">="&DATE('REKAP PERFORMANCE'!$A$1, 'REKAP PERFORMANCE'!$A$4, 1), 'R DATA BNPL'!$E:$E, "<="&EOMONTH(DATE('REKAP PERFORMANCE'!$A$1, 'REKAP PERFORMANCE'!$A$4, 1), 0)) -> 0 | AN21: =SUMIFS('R DATA BNPL'!$H:$H, 'R DATA BNPL'!$F:$F, 'REKAP PERFORMANCE'!AL21, 'R DATA BNPL'!$I:$I, 'REKAP PERFORMANCE'!$AN$18, 'R DATA BNPL'!$D:$D, 'REKAP PERFORMANCE'!$AM$17, 'R DATA BNPL'!$E:$E, ">="&DATE('REKAP PERFORMANCE'!$A$1, 'REKAP PERFORMANCE'!$A$4, 1), 'R DATA BNPL'!$E:$E, "<="&EOMONTH(DATE('REKAP PERFORMANCE'!$A$1, 'REKAP PERFORMANCE'!$A$4, 1), 0)) -> 0 | AO21: =SUMIFS('R DATA BNPL'!$H:$H, 'R DATA BNPL'!$F:$F, 'REKAP PERFORMANCE'!AL21, 'R DATA BNPL'!$I:$I, 'REKAP PERFORMANCE'!$AO$18, 'R DATA BNPL'!$D:$D, 'REKAP PERFORMANCE'!$AM$17, 'R DATA BNPL'!$E:$E, ">="&DATE('REKAP PERFORMANCE'!$A$1, 'REKAP PERFORMANCE'!$A$4, 1), 'R DATA BNPL'!$E:$E, "<="&EOMONTH(DATE('REKAP PERFORMANCE'!$A$1, 'REKAP PERFORMANCE'!$A$4, 1), 0)) -> 0 | AP21: =SUMIFS('R DATA BNPL'!$H:$H, 'R DATA BNPL'!$F:$F, 'REKAP PERFORMANCE'!AL21, 'R DATA BNPL'!$I:$I, 'REKAP PERFORMANCE'!$AP$18, 'R DATA BNPL'!$D:$D, 'REKAP PERFORMANCE'!$AM$17, 'R DATA BNPL'!$E:$E, ">="&DATE('REKAP PERFORMANCE'!$A$1, 'REKAP PERFORMANCE'!$A$4, 1), 'R DATA BNPL'!$E:$E, "<="&EOMONTH(DATE('REKAP PERFORMANCE'!$A$1, 'REKAP PERFORMANCE'!$A$4, 1), 0)) -> 0
A22: =TEXT(B22,"[$-us]dddd") -> Rabu | B22: =IF(MONTH(B21+1)=$A$4,B21+1) -> 46281 | D22: =SUMIFS('R DATA BNPL'!$G:$G,'R DATA BNPL'!$E:$E,B22,'R DATA BNPL'!$F:$F,'REKAP PERFORMANCE'!$D$6) -> 0 | E22: =SUMIFS('R DATA BNPL'!$H:$H,'R DATA BNPL'!$E:$E,DAILY[[#This Row],[Date]],'R DATA BNPL'!$F:$F,'REKAP PERFORMANCE'!$D$6) -> 0 | F22: =SUMIFS('R DATA BNPL'!$G:$G,'R DATA BNPL'!$E:$E,B22,'R DATA BNPL'!$F:$F,'REKAP PERFORMANCE'!$F$6) -> 11817000 | G22: =SUMIFS('R DATA BNPL'!$H:$H,'R DATA BNPL'!$E:$E,DAILY[[#This Row],[Date]],'R DATA BNPL'!$F:$F,'REKAP PERFORMANCE'!$F$6) -> 1 | H22: =SUMIFS('R DATA BNPL'!$G:$G,'R DATA BNPL'!$E:$E,B22,'R DATA BNPL'!$F:$F,'REKAP PERFORMANCE'!$H$6) -> 0 | I22: =SUMIFS('R DATA BNPL'!$H:$H,'R DATA BNPL'!$E:$E,DAILY[[#This Row],[Date]],'R DATA BNPL'!$F:$F,'REKAP PERFORMANCE'!$H$6) -> 0 | J22: =D22+F22+H22 -> 11817000 | K22: =E22+G22+I22 -> 1 | L22: =SUMIFS('R DATA BNPL'!$G:$G,'R DATA BNPL'!$E:$E,B22,'R DATA BNPL'!$F:$F,'REKAP PERFORMANCE'!$L$6) -> 0 | M22: =SUMIFS('R DATA BNPL'!$H:$H,'R DATA BNPL'!$E:$E,DAILY[[#This Row],[Date]],'R DATA BNPL'!$F:$F,'REKAP PERFORMANCE'!$L$6) -> 0 | N22: =SUMIFS('R DATA BNPL'!$G:$G,'R DATA BNPL'!$E:$E,B22,'R DATA BNPL'!$F:$F,'REKAP PERFORMANCE'!$N$6) -> 0 | O22: =SUMIFS('R DATA BNPL'!$H:$H,'R DATA BNPL'!$E:$E,DAILY[[#This Row],[Date]],'R DATA BNPL'!$F:$F,'REKAP PERFORMANCE'!$N$6) -> 0 | P22: =L22+N22 -> 0 | Q22: =M22+O22 -> 0 | R22: =SUMIFS('R DATA BNPL'!$G:$G,'R DATA BNPL'!$E:$E,B22,'R DATA BNPL'!$F:$F,'REKAP PERFORMANCE'!$R$6) -> 0 | S22: =SUMIFS('R DATA BNPL'!$H:$H,'R DATA BNPL'!$E:$E,DAILY[[#This Row],[Date]],'R DATA BNPL'!$F:$F,'REKAP PERFORMANCE'!$R$6) -> 0 | T22: =SUMIFS('R DATA BNPL'!$G:$G,'R DATA BNPL'!$E:$E,B22,'R DATA BNPL'!$F:$F,'REKAP PERFORMANCE'!$T$6) -> 0 | U22: =SUMIFS('R DATA BNPL'!$H:$H,'R DATA BNPL'!$E:$E,DAILY[[#This Row],[Date]],'R DATA BNPL'!$F:$F,'REKAP PERFORMANCE'!$T$6) -> 0 | V22: =R22+T22 -> 0 | W22: =S22+U22 -> 0 | X22: =SUMIFS('R DATA BNPL'!$G:$G,'R DATA BNPL'!$E:$E,B22,'R DATA BNPL'!$F:$F,'REKAP PERFORMANCE'!$X$6) -> 0 | Y22: =SUMIFS('R DATA BNPL'!$H:$H,'R DATA BNPL'!$E:$E,DAILY[[#This Row],[Date]],'R DATA BNPL'!$F:$F,'REKAP PERFORMANCE'!$X$6) -> 0 | Z22: =SUMIFS('R DATA BNPL'!$G:$G,'R DATA BNPL'!$E:$E,B22,'R DATA BNPL'!$F:$F,'REKAP PERFORMANCE'!$Z$6) -> 0 | AA22: =SUMIFS('R DATA BNPL'!$H:$H,'R DATA BNPL'!$E:$E,DAILY[[#This Row],[Date]],'R DATA BNPL'!$F:$F,'REKAP PERFORMANCE'!$Z$6) -> 0 | AB22: =X22+Z22 -> 0 | AC22: =Y22+AA22 -> 0 | AD22: =SUMIFS('R DATA BNPL'!$G:$G,'R DATA BNPL'!$E:$E,B22,'R DATA BNPL'!$F:$F,'REKAP PERFORMANCE'!$AD$6) -> 0 | AE22: =SUMIFS('R DATA BNPL'!$H:$H,'R DATA BNPL'!$E:$E,DAILY[[#This Row],[Date]],'R DATA BNPL'!$F:$F,'REKAP PERFORMANCE'!$AD$6) -> 0 | AH22: =SUMIFS('R DATA BNPL'!$G:$G,'R DATA BNPL'!$E:$E,B22,'R DATA BNPL'!$F:$F,'REKAP PERFORMANCE'!$AH$6) -> 0 | AI22: =SUMIFS('R DATA BNPL'!$G:$G,'R DATA BNPL'!$E:$E,B22,'R DATA BNPL'!$F:$F,'REKAP PERFORMANCE'!$AI$6) -> 0 | AJ22: =SUMIFS('R DATA BNPL'!$G:$G,'R DATA BNPL'!$E:$E,B22,'R DATA BNPL'!$F:$F,'REKAP PERFORMANCE'!$AJ$6) -> 0 | AL22: Rangga Fachrezy | AM22: =SUMIFS('R DATA BNPL'!$H:$H, 'R DATA BNPL'!$F:$F, 'REKAP PERFORMANCE'!AL22, 'R DATA BNPL'!$I:$I, 'REKAP PERFORMANCE'!$AM$18, 'R DATA BNPL'!$D:$D, 'REKAP PERFORMANCE'!$AM$17, 'R DATA BNPL'!$E:$E, ">="&DATE('REKAP PERFORMANCE'!$A$1, 'REKAP PERFORMANCE'!$A$4, 1), 'R DATA BNPL'!$E:$E, "<="&EOMONTH(DATE('REKAP PERFORMANCE'!$A$1, 'REKAP PERFORMANCE'!$A$4, 1), 0)) -> 0 | AN22: =SUMIFS('R DATA BNPL'!$H:$H, 'R DATA BNPL'!$F:$F, 'REKAP PERFORMANCE'!AL22, 'R DATA BNPL'!$I:$I, 'REKAP PERFORMANCE'!$AN$18, 'R DATA BNPL'!$D:$D, 'REKAP PERFORMANCE'!$AM$17, 'R DATA BNPL'!$E:$E, ">="&DATE('REKAP PERFORMANCE'!$A$1, 'REKAP PERFORMANCE'!$A$4, 1), 'R DATA BNPL'!$E:$E, "<="&EOMONTH(DATE('REKAP PERFORMANCE'!$A$1, 'REKAP PERFORMANCE'!$A$4, 1), 0)) -> 0 | AO22: =SUMIFS('R DATA BNPL'!$H:$H, 'R DATA BNPL'!$F:$F, 'REKAP PERFORMANCE'!AL22, 'R DATA BNPL'!$I:$I, 'REKAP PERFORMANCE'!$AO$18, 'R DATA BNPL'!$D:$D, 'REKAP PERFORMANCE'!$AM$17, 'R DATA BNPL'!$E:$E, ">="&DATE('REKAP PERFORMANCE'!$A$1, 'REKAP PERFORMANCE'!$A$4, 1), 'R DATA BNPL'!$E:$E, "<="&EOMONTH(DATE('REKAP PERFORMANCE'!$A$1, 'REKAP PERFORMANCE'!$A$4, 1), 0)) -> 0 | AP22: =SUMIFS('R DATA BNPL'!$H:$H, 'R DATA BNPL'!$F:$F, 'REKAP PERFORMANCE'!AL22, 'R DATA BNPL'!$I:$I, 'REKAP PERFORMANCE'!$AP$18, 'R DATA BNPL'!$D:$D, 'REKAP PERFORMANCE'!$AM$17, 'R DATA BNPL'!$E:$E, ">="&DATE('REKAP PERFORMANCE'!$A$1, 'REKAP PERFORMANCE'!$A$4, 1), 'R DATA BNPL'!$E:$E, "<="&EOMONTH(DATE('REKAP PERFORMANCE'!$A$1, 'REKAP PERFORMANCE'!$A$4, 1), 0)) -> 0
